2020-11-07 07:19:35,939 ERROR HTTPConnectionPool(host='172.17.0.1', port=8080): Read timed out. (read timeout=5)
Traceback (most recent call last):
  File "/usr/local/lib/python3.6/dist-packages/urllib3/connectionpool.py", line 426, in _make_request
    six.raise_from(e, None)
  File "<string>", line 3, in raise_from
  File "/usr/local/lib/python3.6/dist-packages/urllib3/connectionpool.py", line 421, in _make_request
    httplib_response = conn.getresponse()
  File "/usr/lib/python3.6/http/client.py", line 1356, in getresponse
    response.begin()
  File "/usr/lib/python3.6/http/client.py", line 307, in begin
    version, status, reason = self._read_status()
  File "/usr/lib/python3.6/http/client.py", line 268, in _read_status
    line = str(self.fp.readline(_MAXLINE + 1), "iso-8859-1")
  File "/usr/lib/python3.6/socket.py", line 586, in readinto
    return self._sock.recv_into(b)
socket.timeout: timed out

During handling of the above exception, another exception occurred:

Traceback (most recent call last):
  File "/usr/local/lib/python3.6/dist-packages/requests/adapters.py", line 449, in send
    timeout=timeout
  File "/usr/local/lib/python3.6/dist-packages/urllib3/connectionpool.py", line 725, in urlopen
    method, url, error=e, _pool=self, _stacktrace=sys.exc_info()[2]
  File "/usr/local/lib/python3.6/dist-packages/urllib3/util/retry.py", line 403, in increment
    raise six.reraise(type(error), error, _stacktrace)
  File "/usr/local/lib/python3.6/dist-packages/urllib3/packages/six.py", line 735, in reraise
    raise value
  File "/usr/local/lib/python3.6/dist-packages/urllib3/connectionpool.py", line 677, in urlopen
    chunked=chunked,
  File "/usr/local/lib/python3.6/dist-packages/urllib3/connectionpool.py", line 428, in _make_request
    self._raise_timeout(err=e, url=url, timeout_value=read_timeout)
  File "/usr/local/lib/python3.6/dist-packages/urllib3/connectionpool.py", line 336, in _raise_timeout
    self, url, "Read timed out. (read timeout=%s)" % timeout_value
urllib3.exceptions.ReadTimeoutError: HTTPConnectionPool(host='172.17.0.1', port=8080): Read timed out. (read timeout=5)

During handling of the above exception, another exception occurred:

Traceback (most recent call last):
  File "/code/service.py", line 19, in _request
    "Content-Type": "application/json"}, timeout=5).text
  File "/usr/local/lib/python3.6/dist-packages/requests/api.py", line 119, in post
    return request('post', url, data=data, json=json, **kwargs)
  File "/usr/local/lib/python3.6/dist-packages/requests/api.py", line 61, in request
    return session.request(method=method, url=url, **kwargs)
  File "/usr/local/lib/python3.6/dist-packages/requests/sessions.py", line 530, in request
    resp = self.send(prep, **send_kwargs)
  File "/usr/local/lib/python3.6/dist-packages/requests/sessions.py", line 643, in send
    r = adapter.send(request, **kwargs)
  File "/usr/local/lib/python3.6/dist-packages/requests/adapters.py", line 529, in send
    raise ReadTimeout(e, request=request)
requests.exceptions.ReadTimeout: HTTPConnectionPool(host='172.17.0.1', port=8080): Read timed out. (read timeout=5)
2020-11-07 07:19:35,942 ERROR 
Traceback (most recent call last):
  File "/usr/local/lib/python3.6/dist-packages/urllib3/connectionpool.py", line 426, in _make_request
    six.raise_from(e, None)
  File "<string>", line 3, in raise_from
  File "/usr/local/lib/python3.6/dist-packages/urllib3/connectionpool.py", line 421, in _make_request
    httplib_response = conn.getresponse()
  File "/usr/lib/python3.6/http/client.py", line 1356, in getresponse
    response.begin()
  File "/usr/lib/python3.6/http/client.py", line 307, in begin
    version, status, reason = self._read_status()
  File "/usr/lib/python3.6/http/client.py", line 268, in _read_status
    line = str(self.fp.readline(_MAXLINE + 1), "iso-8859-1")
  File "/usr/lib/python3.6/socket.py", line 586, in readinto
    return self._sock.recv_into(b)
socket.timeout: timed out

During handling of the above exception, another exception occurred:

Traceback (most recent call last):
  File "/usr/local/lib/python3.6/dist-packages/requests/adapters.py", line 449, in send
    timeout=timeout
  File "/usr/local/lib/python3.6/dist-packages/urllib3/connectionpool.py", line 725, in urlopen
    method, url, error=e, _pool=self, _stacktrace=sys.exc_info()[2]
  File "/usr/local/lib/python3.6/dist-packages/urllib3/util/retry.py", line 403, in increment
    raise six.reraise(type(error), error, _stacktrace)
  File "/usr/local/lib/python3.6/dist-packages/urllib3/packages/six.py", line 735, in reraise
    raise value
  File "/usr/local/lib/python3.6/dist-packages/urllib3/connectionpool.py", line 677, in urlopen
    chunked=chunked,
  File "/usr/local/lib/python3.6/dist-packages/urllib3/connectionpool.py", line 428, in _make_request
    self._raise_timeout(err=e, url=url, timeout_value=read_timeout)
  File "/usr/local/lib/python3.6/dist-packages/urllib3/connectionpool.py", line 336, in _raise_timeout
    self, url, "Read timed out. (read timeout=%s)" % timeout_value
urllib3.exceptions.ReadTimeoutError: HTTPConnectionPool(host='172.17.0.1', port=8080): Read timed out. (read timeout=5)

During handling of the above exception, another exception occurred:

Traceback (most recent call last):
  File "/code/service.py", line 19, in _request
    "Content-Type": "application/json"}, timeout=5).text
  File "/usr/local/lib/python3.6/dist-packages/requests/api.py", line 119, in post
    return request('post', url, data=data, json=json, **kwargs)
  File "/usr/local/lib/python3.6/dist-packages/requests/api.py", line 61, in request
    return session.request(method=method, url=url, **kwargs)
  File "/usr/local/lib/python3.6/dist-packages/requests/sessions.py", line 530, in request
    resp = self.send(prep, **send_kwargs)
  File "/usr/local/lib/python3.6/dist-packages/requests/sessions.py", line 643, in send
    r = adapter.send(request, **kwargs)
  File "/usr/local/lib/python3.6/dist-packages/requests/adapters.py", line 529, in send
    raise ReadTimeout(e, request=request)
requests.exceptions.ReadTimeout: HTTPConnectionPool(host='172.17.0.1', port=8080): Read timed out. (read timeout=5)

During handling of the above exception, another exception occurred:

Traceback (most recent call last):
  File "/code/service.py", line 42, in <module>
    service.heartbeat()
  File "/code/service.py", line 35, in heartbeat
    self._request(data)
  File "/code/service.py", line 22, in _request
    raise JudgeServiceError("Heartbeat request failed")
exception.JudgeServiceError
2020-11-07 07:20:17,218 ERROR HTTPConnectionPool(host='172.17.0.1', port=8080): Read timed out. (read timeout=5)
Traceback (most recent call last):
  File "/usr/local/lib/python3.6/dist-packages/urllib3/connectionpool.py", line 426, in _make_request
    six.raise_from(e, None)
  File "<string>", line 3, in raise_from
  File "/usr/local/lib/python3.6/dist-packages/urllib3/connectionpool.py", line 421, in _make_request
    httplib_response = conn.getresponse()
  File "/usr/lib/python3.6/http/client.py", line 1356, in getresponse
    response.begin()
  File "/usr/lib/python3.6/http/client.py", line 307, in begin
    version, status, reason = self._read_status()
  File "/usr/lib/python3.6/http/client.py", line 268, in _read_status
    line = str(self.fp.readline(_MAXLINE + 1), "iso-8859-1")
  File "/usr/lib/python3.6/socket.py", line 586, in readinto
    return self._sock.recv_into(b)
socket.timeout: timed out

During handling of the above exception, another exception occurred:

Traceback (most recent call last):
  File "/usr/local/lib/python3.6/dist-packages/requests/adapters.py", line 449, in send
    timeout=timeout
  File "/usr/local/lib/python3.6/dist-packages/urllib3/connectionpool.py", line 725, in urlopen
    method, url, error=e, _pool=self, _stacktrace=sys.exc_info()[2]
  File "/usr/local/lib/python3.6/dist-packages/urllib3/util/retry.py", line 403, in increment
    raise six.reraise(type(error), error, _stacktrace)
  File "/usr/local/lib/python3.6/dist-packages/urllib3/packages/six.py", line 735, in reraise
    raise value
  File "/usr/local/lib/python3.6/dist-packages/urllib3/connectionpool.py", line 677, in urlopen
    chunked=chunked,
  File "/usr/local/lib/python3.6/dist-packages/urllib3/connectionpool.py", line 428, in _make_request
    self._raise_timeout(err=e, url=url, timeout_value=read_timeout)
  File "/usr/local/lib/python3.6/dist-packages/urllib3/connectionpool.py", line 336, in _raise_timeout
    self, url, "Read timed out. (read timeout=%s)" % timeout_value
urllib3.exceptions.ReadTimeoutError: HTTPConnectionPool(host='172.17.0.1', port=8080): Read timed out. (read timeout=5)

During handling of the above exception, another exception occurred:

Traceback (most recent call last):
  File "/code/service.py", line 19, in _request
    "Content-Type": "application/json"}, timeout=5).text
  File "/usr/local/lib/python3.6/dist-packages/requests/api.py", line 119, in post
    return request('post', url, data=data, json=json, **kwargs)
  File "/usr/local/lib/python3.6/dist-packages/requests/api.py", line 61, in request
    return session.request(method=method, url=url, **kwargs)
  File "/usr/local/lib/python3.6/dist-packages/requests/sessions.py", line 530, in request
    resp = self.send(prep, **send_kwargs)
  File "/usr/local/lib/python3.6/dist-packages/requests/sessions.py", line 643, in send
    r = adapter.send(request, **kwargs)
  File "/usr/local/lib/python3.6/dist-packages/requests/adapters.py", line 529, in send
    raise ReadTimeout(e, request=request)
requests.exceptions.ReadTimeout: HTTPConnectionPool(host='172.17.0.1', port=8080): Read timed out. (read timeout=5)
2020-11-07 07:20:17,220 ERROR 
Traceback (most recent call last):
  File "/usr/local/lib/python3.6/dist-packages/urllib3/connectionpool.py", line 426, in _make_request
    six.raise_from(e, None)
  File "<string>", line 3, in raise_from
  File "/usr/local/lib/python3.6/dist-packages/urllib3/connectionpool.py", line 421, in _make_request
    httplib_response = conn.getresponse()
  File "/usr/lib/python3.6/http/client.py", line 1356, in getresponse
    response.begin()
  File "/usr/lib/python3.6/http/client.py", line 307, in begin
    version, status, reason = self._read_status()
  File "/usr/lib/python3.6/http/client.py", line 268, in _read_status
    line = str(self.fp.readline(_MAXLINE + 1), "iso-8859-1")
  File "/usr/lib/python3.6/socket.py", line 586, in readinto
    return self._sock.recv_into(b)
socket.timeout: timed out

During handling of the above exception, another exception occurred:

Traceback (most recent call last):
  File "/usr/local/lib/python3.6/dist-packages/requests/adapters.py", line 449, in send
    timeout=timeout
  File "/usr/local/lib/python3.6/dist-packages/urllib3/connectionpool.py", line 725, in urlopen
    method, url, error=e, _pool=self, _stacktrace=sys.exc_info()[2]
  File "/usr/local/lib/python3.6/dist-packages/urllib3/util/retry.py", line 403, in increment
    raise six.reraise(type(error), error, _stacktrace)
  File "/usr/local/lib/python3.6/dist-packages/urllib3/packages/six.py", line 735, in reraise
    raise value
  File "/usr/local/lib/python3.6/dist-packages/urllib3/connectionpool.py", line 677, in urlopen
    chunked=chunked,
  File "/usr/local/lib/python3.6/dist-packages/urllib3/connectionpool.py", line 428, in _make_request
    self._raise_timeout(err=e, url=url, timeout_value=read_timeout)
  File "/usr/local/lib/python3.6/dist-packages/urllib3/connectionpool.py", line 336, in _raise_timeout
    self, url, "Read timed out. (read timeout=%s)" % timeout_value
urllib3.exceptions.ReadTimeoutError: HTTPConnectionPool(host='172.17.0.1', port=8080): Read timed out. (read timeout=5)

During handling of the above exception, another exception occurred:

Traceback (most recent call last):
  File "/code/service.py", line 19, in _request
    "Content-Type": "application/json"}, timeout=5).text
  File "/usr/local/lib/python3.6/dist-packages/requests/api.py", line 119, in post
    return request('post', url, data=data, json=json, **kwargs)
  File "/usr/local/lib/python3.6/dist-packages/requests/api.py", line 61, in request
    return session.request(method=method, url=url, **kwargs)
  File "/usr/local/lib/python3.6/dist-packages/requests/sessions.py", line 530, in request
    resp = self.send(prep, **send_kwargs)
  File "/usr/local/lib/python3.6/dist-packages/requests/sessions.py", line 643, in send
    r = adapter.send(request, **kwargs)
  File "/usr/local/lib/python3.6/dist-packages/requests/adapters.py", line 529, in send
    raise ReadTimeout(e, request=request)
requests.exceptions.ReadTimeout: HTTPConnectionPool(host='172.17.0.1', port=8080): Read timed out. (read timeout=5)

During handling of the above exception, another exception occurred:

Traceback (most recent call last):
  File "/code/service.py", line 42, in <module>
    service.heartbeat()
  File "/code/service.py", line 35, in heartbeat
    self._request(data)
  File "/code/service.py", line 22, in _request
    raise JudgeServiceError("Heartbeat request failed")
exception.JudgeServiceError
2020-11-07 07:21:03,697 ERROR HTTPConnectionPool(host='172.17.0.1', port=8080): Read timed out. (read timeout=5)
Traceback (most recent call last):
  File "/usr/local/lib/python3.6/dist-packages/urllib3/connectionpool.py", line 426, in _make_request
    six.raise_from(e, None)
  File "<string>", line 3, in raise_from
  File "/usr/local/lib/python3.6/dist-packages/urllib3/connectionpool.py", line 421, in _make_request
    httplib_response = conn.getresponse()
  File "/usr/lib/python3.6/http/client.py", line 1356, in getresponse
    response.begin()
  File "/usr/lib/python3.6/http/client.py", line 307, in begin
    version, status, reason = self._read_status()
  File "/usr/lib/python3.6/http/client.py", line 268, in _read_status
    line = str(self.fp.readline(_MAXLINE + 1), "iso-8859-1")
  File "/usr/lib/python3.6/socket.py", line 586, in readinto
    return self._sock.recv_into(b)
socket.timeout: timed out

During handling of the above exception, another exception occurred:

Traceback (most recent call last):
  File "/usr/local/lib/python3.6/dist-packages/requests/adapters.py", line 449, in send
    timeout=timeout
  File "/usr/local/lib/python3.6/dist-packages/urllib3/connectionpool.py", line 725, in urlopen
    method, url, error=e, _pool=self, _stacktrace=sys.exc_info()[2]
  File "/usr/local/lib/python3.6/dist-packages/urllib3/util/retry.py", line 403, in increment
    raise six.reraise(type(error), error, _stacktrace)
  File "/usr/local/lib/python3.6/dist-packages/urllib3/packages/six.py", line 735, in reraise
    raise value
  File "/usr/local/lib/python3.6/dist-packages/urllib3/connectionpool.py", line 677, in urlopen
    chunked=chunked,
  File "/usr/local/lib/python3.6/dist-packages/urllib3/connectionpool.py", line 428, in _make_request
    self._raise_timeout(err=e, url=url, timeout_value=read_timeout)
  File "/usr/local/lib/python3.6/dist-packages/urllib3/connectionpool.py", line 336, in _raise_timeout
    self, url, "Read timed out. (read timeout=%s)" % timeout_value
urllib3.exceptions.ReadTimeoutError: HTTPConnectionPool(host='172.17.0.1', port=8080): Read timed out. (read timeout=5)

During handling of the above exception, another exception occurred:

Traceback (most recent call last):
  File "/code/service.py", line 19, in _request
    "Content-Type": "application/json"}, timeout=5).text
  File "/usr/local/lib/python3.6/dist-packages/requests/api.py", line 119, in post
    return request('post', url, data=data, json=json, **kwargs)
  File "/usr/local/lib/python3.6/dist-packages/requests/api.py", line 61, in request
    return session.request(method=method, url=url, **kwargs)
  File "/usr/local/lib/python3.6/dist-packages/requests/sessions.py", line 530, in request
    resp = self.send(prep, **send_kwargs)
  File "/usr/local/lib/python3.6/dist-packages/requests/sessions.py", line 643, in send
    r = adapter.send(request, **kwargs)
  File "/usr/local/lib/python3.6/dist-packages/requests/adapters.py", line 529, in send
    raise ReadTimeout(e, request=request)
requests.exceptions.ReadTimeout: HTTPConnectionPool(host='172.17.0.1', port=8080): Read timed out. (read timeout=5)
2020-11-07 07:21:03,700 ERROR 
Traceback (most recent call last):
  File "/usr/local/lib/python3.6/dist-packages/urllib3/connectionpool.py", line 426, in _make_request
    six.raise_from(e, None)
  File "<string>", line 3, in raise_from
  File "/usr/local/lib/python3.6/dist-packages/urllib3/connectionpool.py", line 421, in _make_request
    httplib_response = conn.getresponse()
  File "/usr/lib/python3.6/http/client.py", line 1356, in getresponse
    response.begin()
  File "/usr/lib/python3.6/http/client.py", line 307, in begin
    version, status, reason = self._read_status()
  File "/usr/lib/python3.6/http/client.py", line 268, in _read_status
    line = str(self.fp.readline(_MAXLINE + 1), "iso-8859-1")
  File "/usr/lib/python3.6/socket.py", line 586, in readinto
    return self._sock.recv_into(b)
socket.timeout: timed out

During handling of the above exception, another exception occurred:

Traceback (most recent call last):
  File "/usr/local/lib/python3.6/dist-packages/requests/adapters.py", line 449, in send
    timeout=timeout
  File "/usr/local/lib/python3.6/dist-packages/urllib3/connectionpool.py", line 725, in urlopen
    method, url, error=e, _pool=self, _stacktrace=sys.exc_info()[2]
  File "/usr/local/lib/python3.6/dist-packages/urllib3/util/retry.py", line 403, in increment
    raise six.reraise(type(error), error, _stacktrace)
  File "/usr/local/lib/python3.6/dist-packages/urllib3/packages/six.py", line 735, in reraise
    raise value
  File "/usr/local/lib/python3.6/dist-packages/urllib3/connectionpool.py", line 677, in urlopen
    chunked=chunked,
  File "/usr/local/lib/python3.6/dist-packages/urllib3/connectionpool.py", line 428, in _make_request
    self._raise_timeout(err=e, url=url, timeout_value=read_timeout)
  File "/usr/local/lib/python3.6/dist-packages/urllib3/connectionpool.py", line 336, in _raise_timeout
    self, url, "Read timed out. (read timeout=%s)" % timeout_value
urllib3.exceptions.ReadTimeoutError: HTTPConnectionPool(host='172.17.0.1', port=8080): Read timed out. (read timeout=5)

During handling of the above exception, another exception occurred:

Traceback (most recent call last):
  File "/code/service.py", line 19, in _request
    "Content-Type": "application/json"}, timeout=5).text
  File "/usr/local/lib/python3.6/dist-packages/requests/api.py", line 119, in post
    return request('post', url, data=data, json=json, **kwargs)
  File "/usr/local/lib/python3.6/dist-packages/requests/api.py", line 61, in request
    return session.request(method=method, url=url, **kwargs)
  File "/usr/local/lib/python3.6/dist-packages/requests/sessions.py", line 530, in request
    resp = self.send(prep, **send_kwargs)
  File "/usr/local/lib/python3.6/dist-packages/requests/sessions.py", line 643, in send
    r = adapter.send(request, **kwargs)
  File "/usr/local/lib/python3.6/dist-packages/requests/adapters.py", line 529, in send
    raise ReadTimeout(e, request=request)
requests.exceptions.ReadTimeout: HTTPConnectionPool(host='172.17.0.1', port=8080): Read timed out. (read timeout=5)

During handling of the above exception, another exception occurred:

Traceback (most recent call last):
  File "/code/service.py", line 42, in <module>
    service.heartbeat()
  File "/code/service.py", line 35, in heartbeat
    self._request(data)
  File "/code/service.py", line 22, in _request
    raise JudgeServiceError("Heartbeat request failed")
exception.JudgeServiceError
2020-11-07 07:21:50,165 ERROR HTTPConnectionPool(host='172.17.0.1', port=8080): Read timed out. (read timeout=5)
Traceback (most recent call last):
  File "/usr/local/lib/python3.6/dist-packages/urllib3/connectionpool.py", line 426, in _make_request
    six.raise_from(e, None)
  File "<string>", line 3, in raise_from
  File "/usr/local/lib/python3.6/dist-packages/urllib3/connectionpool.py", line 421, in _make_request
    httplib_response = conn.getresponse()
  File "/usr/lib/python3.6/http/client.py", line 1356, in getresponse
    response.begin()
  File "/usr/lib/python3.6/http/client.py", line 307, in begin
    version, status, reason = self._read_status()
  File "/usr/lib/python3.6/http/client.py", line 268, in _read_status
    line = str(self.fp.readline(_MAXLINE + 1), "iso-8859-1")
  File "/usr/lib/python3.6/socket.py", line 586, in readinto
    return self._sock.recv_into(b)
socket.timeout: timed out

During handling of the above exception, another exception occurred:

Traceback (most recent call last):
  File "/usr/local/lib/python3.6/dist-packages/requests/adapters.py", line 449, in send
    timeout=timeout
  File "/usr/local/lib/python3.6/dist-packages/urllib3/connectionpool.py", line 725, in urlopen
    method, url, error=e, _pool=self, _stacktrace=sys.exc_info()[2]
  File "/usr/local/lib/python3.6/dist-packages/urllib3/util/retry.py", line 403, in increment
    raise six.reraise(type(error), error, _stacktrace)
  File "/usr/local/lib/python3.6/dist-packages/urllib3/packages/six.py", line 735, in reraise
    raise value
  File "/usr/local/lib/python3.6/dist-packages/urllib3/connectionpool.py", line 677, in urlopen
    chunked=chunked,
  File "/usr/local/lib/python3.6/dist-packages/urllib3/connectionpool.py", line 428, in _make_request
    self._raise_timeout(err=e, url=url, timeout_value=read_timeout)
  File "/usr/local/lib/python3.6/dist-packages/urllib3/connectionpool.py", line 336, in _raise_timeout
    self, url, "Read timed out. (read timeout=%s)" % timeout_value
urllib3.exceptions.ReadTimeoutError: HTTPConnectionPool(host='172.17.0.1', port=8080): Read timed out. (read timeout=5)

During handling of the above exception, another exception occurred:

Traceback (most recent call last):
  File "/code/service.py", line 19, in _request
    "Content-Type": "application/json"}, timeout=5).text
  File "/usr/local/lib/python3.6/dist-packages/requests/api.py", line 119, in post
    return request('post', url, data=data, json=json, **kwargs)
  File "/usr/local/lib/python3.6/dist-packages/requests/api.py", line 61, in request
    return session.request(method=method, url=url, **kwargs)
  File "/usr/local/lib/python3.6/dist-packages/requests/sessions.py", line 530, in request
    resp = self.send(prep, **send_kwargs)
  File "/usr/local/lib/python3.6/dist-packages/requests/sessions.py", line 643, in send
    r = adapter.send(request, **kwargs)
  File "/usr/local/lib/python3.6/dist-packages/requests/adapters.py", line 529, in send
    raise ReadTimeout(e, request=request)
requests.exceptions.ReadTimeout: HTTPConnectionPool(host='172.17.0.1', port=8080): Read timed out. (read timeout=5)
2020-11-07 07:21:50,168 ERROR 
Traceback (most recent call last):
  File "/usr/local/lib/python3.6/dist-packages/urllib3/connectionpool.py", line 426, in _make_request
    six.raise_from(e, None)
  File "<string>", line 3, in raise_from
  File "/usr/local/lib/python3.6/dist-packages/urllib3/connectionpool.py", line 421, in _make_request
    httplib_response = conn.getresponse()
  File "/usr/lib/python3.6/http/client.py", line 1356, in getresponse
    response.begin()
  File "/usr/lib/python3.6/http/client.py", line 307, in begin
    version, status, reason = self._read_status()
  File "/usr/lib/python3.6/http/client.py", line 268, in _read_status
    line = str(self.fp.readline(_MAXLINE + 1), "iso-8859-1")
  File "/usr/lib/python3.6/socket.py", line 586, in readinto
    return self._sock.recv_into(b)
socket.timeout: timed out

During handling of the above exception, another exception occurred:

Traceback (most recent call last):
  File "/usr/local/lib/python3.6/dist-packages/requests/adapters.py", line 449, in send
    timeout=timeout
  File "/usr/local/lib/python3.6/dist-packages/urllib3/connectionpool.py", line 725, in urlopen
    method, url, error=e, _pool=self, _stacktrace=sys.exc_info()[2]
  File "/usr/local/lib/python3.6/dist-packages/urllib3/util/retry.py", line 403, in increment
    raise six.reraise(type(error), error, _stacktrace)
  File "/usr/local/lib/python3.6/dist-packages/urllib3/packages/six.py", line 735, in reraise
    raise value
  File "/usr/local/lib/python3.6/dist-packages/urllib3/connectionpool.py", line 677, in urlopen
    chunked=chunked,
  File "/usr/local/lib/python3.6/dist-packages/urllib3/connectionpool.py", line 428, in _make_request
    self._raise_timeout(err=e, url=url, timeout_value=read_timeout)
  File "/usr/local/lib/python3.6/dist-packages/urllib3/connectionpool.py", line 336, in _raise_timeout
    self, url, "Read timed out. (read timeout=%s)" % timeout_value
urllib3.exceptions.ReadTimeoutError: HTTPConnectionPool(host='172.17.0.1', port=8080): Read timed out. (read timeout=5)

During handling of the above exception, another exception occurred:

Traceback (most recent call last):
  File "/code/service.py", line 19, in _request
    "Content-Type": "application/json"}, timeout=5).text
  File "/usr/local/lib/python3.6/dist-packages/requests/api.py", line 119, in post
    return request('post', url, data=data, json=json, **kwargs)
  File "/usr/local/lib/python3.6/dist-packages/requests/api.py", line 61, in request
    return session.request(method=method, url=url, **kwargs)
  File "/usr/local/lib/python3.6/dist-packages/requests/sessions.py", line 530, in request
    resp = self.send(prep, **send_kwargs)
  File "/usr/local/lib/python3.6/dist-packages/requests/sessions.py", line 643, in send
    r = adapter.send(request, **kwargs)
  File "/usr/local/lib/python3.6/dist-packages/requests/adapters.py", line 529, in send
    raise ReadTimeout(e, request=request)
requests.exceptions.ReadTimeout: HTTPConnectionPool(host='172.17.0.1', port=8080): Read timed out. (read timeout=5)

During handling of the above exception, another exception occurred:

Traceback (most recent call last):
  File "/code/service.py", line 42, in <module>
    service.heartbeat()
  File "/code/service.py", line 35, in heartbeat
    self._request(data)
  File "/code/service.py", line 22, in _request
    raise JudgeServiceError("Heartbeat request failed")
exception.JudgeServiceError
2020-11-07 07:22:36,606 ERROR HTTPConnectionPool(host='172.17.0.1', port=8080): Read timed out. (read timeout=5)
Traceback (most recent call last):
  File "/usr/local/lib/python3.6/dist-packages/urllib3/connectionpool.py", line 426, in _make_request
    six.raise_from(e, None)
  File "<string>", line 3, in raise_from
  File "/usr/local/lib/python3.6/dist-packages/urllib3/connectionpool.py", line 421, in _make_request
    httplib_response = conn.getresponse()
  File "/usr/lib/python3.6/http/client.py", line 1356, in getresponse
    response.begin()
  File "/usr/lib/python3.6/http/client.py", line 307, in begin
    version, status, reason = self._read_status()
  File "/usr/lib/python3.6/http/client.py", line 268, in _read_status
    line = str(self.fp.readline(_MAXLINE + 1), "iso-8859-1")
  File "/usr/lib/python3.6/socket.py", line 586, in readinto
    return self._sock.recv_into(b)
socket.timeout: timed out

During handling of the above exception, another exception occurred:

Traceback (most recent call last):
  File "/usr/local/lib/python3.6/dist-packages/requests/adapters.py", line 449, in send
    timeout=timeout
  File "/usr/local/lib/python3.6/dist-packages/urllib3/connectionpool.py", line 725, in urlopen
    method, url, error=e, _pool=self, _stacktrace=sys.exc_info()[2]
  File "/usr/local/lib/python3.6/dist-packages/urllib3/util/retry.py", line 403, in increment
    raise six.reraise(type(error), error, _stacktrace)
  File "/usr/local/lib/python3.6/dist-packages/urllib3/packages/six.py", line 735, in reraise
    raise value
  File "/usr/local/lib/python3.6/dist-packages/urllib3/connectionpool.py", line 677, in urlopen
    chunked=chunked,
  File "/usr/local/lib/python3.6/dist-packages/urllib3/connectionpool.py", line 428, in _make_request
    self._raise_timeout(err=e, url=url, timeout_value=read_timeout)
  File "/usr/local/lib/python3.6/dist-packages/urllib3/connectionpool.py", line 336, in _raise_timeout
    self, url, "Read timed out. (read timeout=%s)" % timeout_value
urllib3.exceptions.ReadTimeoutError: HTTPConnectionPool(host='172.17.0.1', port=8080): Read timed out. (read timeout=5)

During handling of the above exception, another exception occurred:

Traceback (most recent call last):
  File "/code/service.py", line 19, in _request
    "Content-Type": "application/json"}, timeout=5).text
  File "/usr/local/lib/python3.6/dist-packages/requests/api.py", line 119, in post
    return request('post', url, data=data, json=json, **kwargs)
  File "/usr/local/lib/python3.6/dist-packages/requests/api.py", line 61, in request
    return session.request(method=method, url=url, **kwargs)
  File "/usr/local/lib/python3.6/dist-packages/requests/sessions.py", line 530, in request
    resp = self.send(prep, **send_kwargs)
  File "/usr/local/lib/python3.6/dist-packages/requests/sessions.py", line 643, in send
    r = adapter.send(request, **kwargs)
  File "/usr/local/lib/python3.6/dist-packages/requests/adapters.py", line 529, in send
    raise ReadTimeout(e, request=request)
requests.exceptions.ReadTimeout: HTTPConnectionPool(host='172.17.0.1', port=8080): Read timed out. (read timeout=5)
2020-11-07 07:22:36,609 ERROR 
Traceback (most recent call last):
  File "/usr/local/lib/python3.6/dist-packages/urllib3/connectionpool.py", line 426, in _make_request
    six.raise_from(e, None)
  File "<string>", line 3, in raise_from
  File "/usr/local/lib/python3.6/dist-packages/urllib3/connectionpool.py", line 421, in _make_request
    httplib_response = conn.getresponse()
  File "/usr/lib/python3.6/http/client.py", line 1356, in getresponse
    response.begin()
  File "/usr/lib/python3.6/http/client.py", line 307, in begin
    version, status, reason = self._read_status()
  File "/usr/lib/python3.6/http/client.py", line 268, in _read_status
    line = str(self.fp.readline(_MAXLINE + 1), "iso-8859-1")
  File "/usr/lib/python3.6/socket.py", line 586, in readinto
    return self._sock.recv_into(b)
socket.timeout: timed out

During handling of the above exception, another exception occurred:

Traceback (most recent call last):
  File "/usr/local/lib/python3.6/dist-packages/requests/adapters.py", line 449, in send
    timeout=timeout
  File "/usr/local/lib/python3.6/dist-packages/urllib3/connectionpool.py", line 725, in urlopen
    method, url, error=e, _pool=self, _stacktrace=sys.exc_info()[2]
  File "/usr/local/lib/python3.6/dist-packages/urllib3/util/retry.py", line 403, in increment
    raise six.reraise(type(error), error, _stacktrace)
  File "/usr/local/lib/python3.6/dist-packages/urllib3/packages/six.py", line 735, in reraise
    raise value
  File "/usr/local/lib/python3.6/dist-packages/urllib3/connectionpool.py", line 677, in urlopen
    chunked=chunked,
  File "/usr/local/lib/python3.6/dist-packages/urllib3/connectionpool.py", line 428, in _make_request
    self._raise_timeout(err=e, url=url, timeout_value=read_timeout)
  File "/usr/local/lib/python3.6/dist-packages/urllib3/connectionpool.py", line 336, in _raise_timeout
    self, url, "Read timed out. (read timeout=%s)" % timeout_value
urllib3.exceptions.ReadTimeoutError: HTTPConnectionPool(host='172.17.0.1', port=8080): Read timed out. (read timeout=5)

During handling of the above exception, another exception occurred:

Traceback (most recent call last):
  File "/code/service.py", line 19, in _request
    "Content-Type": "application/json"}, timeout=5).text
  File "/usr/local/lib/python3.6/dist-packages/requests/api.py", line 119, in post
    return request('post', url, data=data, json=json, **kwargs)
  File "/usr/local/lib/python3.6/dist-packages/requests/api.py", line 61, in request
    return session.request(method=method, url=url, **kwargs)
  File "/usr/local/lib/python3.6/dist-packages/requests/sessions.py", line 530, in request
    resp = self.send(prep, **send_kwargs)
  File "/usr/local/lib/python3.6/dist-packages/requests/sessions.py", line 643, in send
    r = adapter.send(request, **kwargs)
  File "/usr/local/lib/python3.6/dist-packages/requests/adapters.py", line 529, in send
    raise ReadTimeout(e, request=request)
requests.exceptions.ReadTimeout: HTTPConnectionPool(host='172.17.0.1', port=8080): Read timed out. (read timeout=5)

During handling of the above exception, another exception occurred:

Traceback (most recent call last):
  File "/code/service.py", line 42, in <module>
    service.heartbeat()
  File "/code/service.py", line 35, in heartbeat
    self._request(data)
  File "/code/service.py", line 22, in _request
    raise JudgeServiceError("Heartbeat request failed")
exception.JudgeServiceError
2020-11-07 07:23:18,043 ERROR HTTPConnectionPool(host='172.17.0.1', port=8080): Max retries exceeded with url: /judge_server/heartbeat (Caused by NewConnectionError('<urllib3.connection.HTTPConnection object at 0x7f384c5b8a90>: Failed to establish a new connection: [Errno 111] Connection refused',))
Traceback (most recent call last):
  File "/usr/local/lib/python3.6/dist-packages/urllib3/connection.py", line 160, in _new_conn
    (self._dns_host, self.port), self.timeout, **extra_kw
  File "/usr/local/lib/python3.6/dist-packages/urllib3/util/connection.py", line 84, in create_connection
    raise err
  File "/usr/local/lib/python3.6/dist-packages/urllib3/util/connection.py", line 74, in create_connection
    sock.connect(sa)
ConnectionRefusedError: [Errno 111] Connection refused

During handling of the above exception, another exception occurred:

Traceback (most recent call last):
  File "/usr/local/lib/python3.6/dist-packages/urllib3/connectionpool.py", line 677, in urlopen
    chunked=chunked,
  File "/usr/local/lib/python3.6/dist-packages/urllib3/connectionpool.py", line 392, in _make_request
    conn.request(method, url, **httplib_request_kw)
  File "/usr/lib/python3.6/http/client.py", line 1264, in request
    self._send_request(method, url, body, headers, encode_chunked)
  File "/usr/lib/python3.6/http/client.py", line 1310, in _send_request
    self.endheaders(body, encode_chunked=encode_chunked)
  File "/usr/lib/python3.6/http/client.py", line 1259, in endheaders
    self._send_output(message_body, encode_chunked=encode_chunked)
  File "/usr/lib/python3.6/http/client.py", line 1038, in _send_output
    self.send(msg)
  File "/usr/lib/python3.6/http/client.py", line 976, in send
    self.connect()
  File "/usr/local/lib/python3.6/dist-packages/urllib3/connection.py", line 187, in connect
    conn = self._new_conn()
  File "/usr/local/lib/python3.6/dist-packages/urllib3/connection.py", line 172, in _new_conn
    self, "Failed to establish a new connection: %s" % e
urllib3.exceptions.NewConnectionError: <urllib3.connection.HTTPConnection object at 0x7f384c5b8a90>: Failed to establish a new connection: [Errno 111] Connection refused

During handling of the above exception, another exception occurred:

Traceback (most recent call last):
  File "/usr/local/lib/python3.6/dist-packages/requests/adapters.py", line 449, in send
    timeout=timeout
  File "/usr/local/lib/python3.6/dist-packages/urllib3/connectionpool.py", line 725, in urlopen
    method, url, error=e, _pool=self, _stacktrace=sys.exc_info()[2]
  File "/usr/local/lib/python3.6/dist-packages/urllib3/util/retry.py", line 439, in increment
    raise MaxRetryError(_pool, url, error or ResponseError(cause))
urllib3.exceptions.MaxRetryError: HTTPConnectionPool(host='172.17.0.1', port=8080): Max retries exceeded with url: /judge_server/heartbeat (Caused by NewConnectionError('<urllib3.connection.HTTPConnection object at 0x7f384c5b8a90>: Failed to establish a new connection: [Errno 111] Connection refused',))

During handling of the above exception, another exception occurred:

Traceback (most recent call last):
  File "/code/service.py", line 19, in _request
    "Content-Type": "application/json"}, timeout=5).text
  File "/usr/local/lib/python3.6/dist-packages/requests/api.py", line 119, in post
    return request('post', url, data=data, json=json, **kwargs)
  File "/usr/local/lib/python3.6/dist-packages/requests/api.py", line 61, in request
    return session.request(method=method, url=url, **kwargs)
  File "/usr/local/lib/python3.6/dist-packages/requests/sessions.py", line 530, in request
    resp = self.send(prep, **send_kwargs)
  File "/usr/local/lib/python3.6/dist-packages/requests/sessions.py", line 643, in send
    r = adapter.send(request, **kwargs)
  File "/usr/local/lib/python3.6/dist-packages/requests/adapters.py", line 516, in send
    raise ConnectionError(e, request=request)
requests.exceptions.ConnectionError: HTTPConnectionPool(host='172.17.0.1', port=8080): Max retries exceeded with url: /judge_server/heartbeat (Caused by NewConnectionError('<urllib3.connection.HTTPConnection object at 0x7f384c5b8a90>: Failed to establish a new connection: [Errno 111] Connection refused',))
2020-11-07 07:23:18,044 ERROR 
Traceback (most recent call last):
  File "/usr/local/lib/python3.6/dist-packages/urllib3/connection.py", line 160, in _new_conn
    (self._dns_host, self.port), self.timeout, **extra_kw
  File "/usr/local/lib/python3.6/dist-packages/urllib3/util/connection.py", line 84, in create_connection
    raise err
  File "/usr/local/lib/python3.6/dist-packages/urllib3/util/connection.py", line 74, in create_connection
    sock.connect(sa)
ConnectionRefusedError: [Errno 111] Connection refused

During handling of the above exception, another exception occurred:

Traceback (most recent call last):
  File "/usr/local/lib/python3.6/dist-packages/urllib3/connectionpool.py", line 677, in urlopen
    chunked=chunked,
  File "/usr/local/lib/python3.6/dist-packages/urllib3/connectionpool.py", line 392, in _make_request
    conn.request(method, url, **httplib_request_kw)
  File "/usr/lib/python3.6/http/client.py", line 1264, in request
    self._send_request(method, url, body, headers, encode_chunked)
  File "/usr/lib/python3.6/http/client.py", line 1310, in _send_request
    self.endheaders(body, encode_chunked=encode_chunked)
  File "/usr/lib/python3.6/http/client.py", line 1259, in endheaders
    self._send_output(message_body, encode_chunked=encode_chunked)
  File "/usr/lib/python3.6/http/client.py", line 1038, in _send_output
    self.send(msg)
  File "/usr/lib/python3.6/http/client.py", line 976, in send
    self.connect()
  File "/usr/local/lib/python3.6/dist-packages/urllib3/connection.py", line 187, in connect
    conn = self._new_conn()
  File "/usr/local/lib/python3.6/dist-packages/urllib3/connection.py", line 172, in _new_conn
    self, "Failed to establish a new connection: %s" % e
urllib3.exceptions.NewConnectionError: <urllib3.connection.HTTPConnection object at 0x7f384c5b8a90>: Failed to establish a new connection: [Errno 111] Connection refused

During handling of the above exception, another exception occurred:

Traceback (most recent call last):
  File "/usr/local/lib/python3.6/dist-packages/requests/adapters.py", line 449, in send
    timeout=timeout
  File "/usr/local/lib/python3.6/dist-packages/urllib3/connectionpool.py", line 725, in urlopen
    method, url, error=e, _pool=self, _stacktrace=sys.exc_info()[2]
  File "/usr/local/lib/python3.6/dist-packages/urllib3/util/retry.py", line 439, in increment
    raise MaxRetryError(_pool, url, error or ResponseError(cause))
urllib3.exceptions.MaxRetryError: HTTPConnectionPool(host='172.17.0.1', port=8080): Max retries exceeded with url: /judge_server/heartbeat (Caused by NewConnectionError('<urllib3.connection.HTTPConnection object at 0x7f384c5b8a90>: Failed to establish a new connection: [Errno 111] Connection refused',))

During handling of the above exception, another exception occurred:

Traceback (most recent call last):
  File "/code/service.py", line 19, in _request
    "Content-Type": "application/json"}, timeout=5).text
  File "/usr/local/lib/python3.6/dist-packages/requests/api.py", line 119, in post
    return request('post', url, data=data, json=json, **kwargs)
  File "/usr/local/lib/python3.6/dist-packages/requests/api.py", line 61, in request
    return session.request(method=method, url=url, **kwargs)
  File "/usr/local/lib/python3.6/dist-packages/requests/sessions.py", line 530, in request
    resp = self.send(prep, **send_kwargs)
  File "/usr/local/lib/python3.6/dist-packages/requests/sessions.py", line 643, in send
    r = adapter.send(request, **kwargs)
  File "/usr/local/lib/python3.6/dist-packages/requests/adapters.py", line 516, in send
    raise ConnectionError(e, request=request)
requests.exceptions.ConnectionError: HTTPConnectionPool(host='172.17.0.1', port=8080): Max retries exceeded with url: /judge_server/heartbeat (Caused by NewConnectionError('<urllib3.connection.HTTPConnection object at 0x7f384c5b8a90>: Failed to establish a new connection: [Errno 111] Connection refused',))

During handling of the above exception, another exception occurred:

Traceback (most recent call last):
  File "/code/service.py", line 42, in <module>
    service.heartbeat()
  File "/code/service.py", line 35, in heartbeat
    self._request(data)
  File "/code/service.py", line 22, in _request
    raise JudgeServiceError("Heartbeat request failed")
exception.JudgeServiceError
2020-11-07 07:57:39,447 ERROR 
Traceback (most recent call last):
  File "/code/server.py", line 192, in server
    ret = {"err": None, "data": getattr(JudgeServer, path)(**data)}
  File "/code/server.py", line 99, in judge
    output_dir=submission_dir)
  File "/code/compiler.py", line 44, in compile
    raise CompileError(error)
exception.CompileError
2020-11-07 07:59:51,539 ERROR HTTPConnectionPool(host='172.17.0.1', port=8080): Max retries exceeded with url: /judge_server/heartbeat (Caused by NewConnectionError('<urllib3.connection.HTTPConnection object at 0x7fd0f532cac8>: Failed to establish a new connection: [Errno 111] Connection refused',))
Traceback (most recent call last):
  File "/usr/local/lib/python3.6/dist-packages/urllib3/connection.py", line 160, in _new_conn
    (self._dns_host, self.port), self.timeout, **extra_kw
  File "/usr/local/lib/python3.6/dist-packages/urllib3/util/connection.py", line 84, in create_connection
    raise err
  File "/usr/local/lib/python3.6/dist-packages/urllib3/util/connection.py", line 74, in create_connection
    sock.connect(sa)
ConnectionRefusedError: [Errno 111] Connection refused

During handling of the above exception, another exception occurred:

Traceback (most recent call last):
  File "/usr/local/lib/python3.6/dist-packages/urllib3/connectionpool.py", line 677, in urlopen
    chunked=chunked,
  File "/usr/local/lib/python3.6/dist-packages/urllib3/connectionpool.py", line 392, in _make_request
    conn.request(method, url, **httplib_request_kw)
  File "/usr/lib/python3.6/http/client.py", line 1264, in request
    self._send_request(method, url, body, headers, encode_chunked)
  File "/usr/lib/python3.6/http/client.py", line 1310, in _send_request
    self.endheaders(body, encode_chunked=encode_chunked)
  File "/usr/lib/python3.6/http/client.py", line 1259, in endheaders
    self._send_output(message_body, encode_chunked=encode_chunked)
  File "/usr/lib/python3.6/http/client.py", line 1038, in _send_output
    self.send(msg)
  File "/usr/lib/python3.6/http/client.py", line 976, in send
    self.connect()
  File "/usr/local/lib/python3.6/dist-packages/urllib3/connection.py", line 187, in connect
    conn = self._new_conn()
  File "/usr/local/lib/python3.6/dist-packages/urllib3/connection.py", line 172, in _new_conn
    self, "Failed to establish a new connection: %s" % e
urllib3.exceptions.NewConnectionError: <urllib3.connection.HTTPConnection object at 0x7fd0f532cac8>: Failed to establish a new connection: [Errno 111] Connection refused

During handling of the above exception, another exception occurred:

Traceback (most recent call last):
  File "/usr/local/lib/python3.6/dist-packages/requests/adapters.py", line 449, in send
    timeout=timeout
  File "/usr/local/lib/python3.6/dist-packages/urllib3/connectionpool.py", line 725, in urlopen
    method, url, error=e, _pool=self, _stacktrace=sys.exc_info()[2]
  File "/usr/local/lib/python3.6/dist-packages/urllib3/util/retry.py", line 439, in increment
    raise MaxRetryError(_pool, url, error or ResponseError(cause))
urllib3.exceptions.MaxRetryError: HTTPConnectionPool(host='172.17.0.1', port=8080): Max retries exceeded with url: /judge_server/heartbeat (Caused by NewConnectionError('<urllib3.connection.HTTPConnection object at 0x7fd0f532cac8>: Failed to establish a new connection: [Errno 111] Connection refused',))

During handling of the above exception, another exception occurred:

Traceback (most recent call last):
  File "/code/service.py", line 19, in _request
    "Content-Type": "application/json"}, timeout=5).text
  File "/usr/local/lib/python3.6/dist-packages/requests/api.py", line 119, in post
    return request('post', url, data=data, json=json, **kwargs)
  File "/usr/local/lib/python3.6/dist-packages/requests/api.py", line 61, in request
    return session.request(method=method, url=url, **kwargs)
  File "/usr/local/lib/python3.6/dist-packages/requests/sessions.py", line 530, in request
    resp = self.send(prep, **send_kwargs)
  File "/usr/local/lib/python3.6/dist-packages/requests/sessions.py", line 643, in send
    r = adapter.send(request, **kwargs)
  File "/usr/local/lib/python3.6/dist-packages/requests/adapters.py", line 516, in send
    raise ConnectionError(e, request=request)
requests.exceptions.ConnectionError: HTTPConnectionPool(host='172.17.0.1', port=8080): Max retries exceeded with url: /judge_server/heartbeat (Caused by NewConnectionError('<urllib3.connection.HTTPConnection object at 0x7fd0f532cac8>: Failed to establish a new connection: [Errno 111] Connection refused',))
2020-11-07 07:59:51,540 ERROR 
Traceback (most recent call last):
  File "/usr/local/lib/python3.6/dist-packages/urllib3/connection.py", line 160, in _new_conn
    (self._dns_host, self.port), self.timeout, **extra_kw
  File "/usr/local/lib/python3.6/dist-packages/urllib3/util/connection.py", line 84, in create_connection
    raise err
  File "/usr/local/lib/python3.6/dist-packages/urllib3/util/connection.py", line 74, in create_connection
    sock.connect(sa)
ConnectionRefusedError: [Errno 111] Connection refused

During handling of the above exception, another exception occurred:

Traceback (most recent call last):
  File "/usr/local/lib/python3.6/dist-packages/urllib3/connectionpool.py", line 677, in urlopen
    chunked=chunked,
  File "/usr/local/lib/python3.6/dist-packages/urllib3/connectionpool.py", line 392, in _make_request
    conn.request(method, url, **httplib_request_kw)
  File "/usr/lib/python3.6/http/client.py", line 1264, in request
    self._send_request(method, url, body, headers, encode_chunked)
  File "/usr/lib/python3.6/http/client.py", line 1310, in _send_request
    self.endheaders(body, encode_chunked=encode_chunked)
  File "/usr/lib/python3.6/http/client.py", line 1259, in endheaders
    self._send_output(message_body, encode_chunked=encode_chunked)
  File "/usr/lib/python3.6/http/client.py", line 1038, in _send_output
    self.send(msg)
  File "/usr/lib/python3.6/http/client.py", line 976, in send
    self.connect()
  File "/usr/local/lib/python3.6/dist-packages/urllib3/connection.py", line 187, in connect
    conn = self._new_conn()
  File "/usr/local/lib/python3.6/dist-packages/urllib3/connection.py", line 172, in _new_conn
    self, "Failed to establish a new connection: %s" % e
urllib3.exceptions.NewConnectionError: <urllib3.connection.HTTPConnection object at 0x7fd0f532cac8>: Failed to establish a new connection: [Errno 111] Connection refused

During handling of the above exception, another exception occurred:

Traceback (most recent call last):
  File "/usr/local/lib/python3.6/dist-packages/requests/adapters.py", line 449, in send
    timeout=timeout
  File "/usr/local/lib/python3.6/dist-packages/urllib3/connectionpool.py", line 725, in urlopen
    method, url, error=e, _pool=self, _stacktrace=sys.exc_info()[2]
  File "/usr/local/lib/python3.6/dist-packages/urllib3/util/retry.py", line 439, in increment
    raise MaxRetryError(_pool, url, error or ResponseError(cause))
urllib3.exceptions.MaxRetryError: HTTPConnectionPool(host='172.17.0.1', port=8080): Max retries exceeded with url: /judge_server/heartbeat (Caused by NewConnectionError('<urllib3.connection.HTTPConnection object at 0x7fd0f532cac8>: Failed to establish a new connection: [Errno 111] Connection refused',))

During handling of the above exception, another exception occurred:

Traceback (most recent call last):
  File "/code/service.py", line 19, in _request
    "Content-Type": "application/json"}, timeout=5).text
  File "/usr/local/lib/python3.6/dist-packages/requests/api.py", line 119, in post
    return request('post', url, data=data, json=json, **kwargs)
  File "/usr/local/lib/python3.6/dist-packages/requests/api.py", line 61, in request
    return session.request(method=method, url=url, **kwargs)
  File "/usr/local/lib/python3.6/dist-packages/requests/sessions.py", line 530, in request
    resp = self.send(prep, **send_kwargs)
  File "/usr/local/lib/python3.6/dist-packages/requests/sessions.py", line 643, in send
    r = adapter.send(request, **kwargs)
  File "/usr/local/lib/python3.6/dist-packages/requests/adapters.py", line 516, in send
    raise ConnectionError(e, request=request)
requests.exceptions.ConnectionError: HTTPConnectionPool(host='172.17.0.1', port=8080): Max retries exceeded with url: /judge_server/heartbeat (Caused by NewConnectionError('<urllib3.connection.HTTPConnection object at 0x7fd0f532cac8>: Failed to establish a new connection: [Errno 111] Connection refused',))

During handling of the above exception, another exception occurred:

Traceback (most recent call last):
  File "/code/service.py", line 42, in <module>
    service.heartbeat()
  File "/code/service.py", line 35, in heartbeat
    self._request(data)
  File "/code/service.py", line 22, in _request
    raise JudgeServiceError("Heartbeat request failed")
exception.JudgeServiceError
2020-11-07 07:59:56,715 ERROR HTTPConnectionPool(host='172.17.0.1', port=8080): Max retries exceeded with url: /judge_server/heartbeat (Caused by NewConnectionError('<urllib3.connection.HTTPConnection object at 0x7ff3054e0ac8>: Failed to establish a new connection: [Errno 111] Connection refused',))
Traceback (most recent call last):
  File "/usr/local/lib/python3.6/dist-packages/urllib3/connection.py", line 160, in _new_conn
    (self._dns_host, self.port), self.timeout, **extra_kw
  File "/usr/local/lib/python3.6/dist-packages/urllib3/util/connection.py", line 84, in create_connection
    raise err
  File "/usr/local/lib/python3.6/dist-packages/urllib3/util/connection.py", line 74, in create_connection
    sock.connect(sa)
ConnectionRefusedError: [Errno 111] Connection refused

During handling of the above exception, another exception occurred:

Traceback (most recent call last):
  File "/usr/local/lib/python3.6/dist-packages/urllib3/connectionpool.py", line 677, in urlopen
    chunked=chunked,
  File "/usr/local/lib/python3.6/dist-packages/urllib3/connectionpool.py", line 392, in _make_request
    conn.request(method, url, **httplib_request_kw)
  File "/usr/lib/python3.6/http/client.py", line 1264, in request
    self._send_request(method, url, body, headers, encode_chunked)
  File "/usr/lib/python3.6/http/client.py", line 1310, in _send_request
    self.endheaders(body, encode_chunked=encode_chunked)
  File "/usr/lib/python3.6/http/client.py", line 1259, in endheaders
    self._send_output(message_body, encode_chunked=encode_chunked)
  File "/usr/lib/python3.6/http/client.py", line 1038, in _send_output
    self.send(msg)
  File "/usr/lib/python3.6/http/client.py", line 976, in send
    self.connect()
  File "/usr/local/lib/python3.6/dist-packages/urllib3/connection.py", line 187, in connect
    conn = self._new_conn()
  File "/usr/local/lib/python3.6/dist-packages/urllib3/connection.py", line 172, in _new_conn
    self, "Failed to establish a new connection: %s" % e
urllib3.exceptions.NewConnectionError: <urllib3.connection.HTTPConnection object at 0x7ff3054e0ac8>: Failed to establish a new connection: [Errno 111] Connection refused

During handling of the above exception, another exception occurred:

Traceback (most recent call last):
  File "/usr/local/lib/python3.6/dist-packages/requests/adapters.py", line 449, in send
    timeout=timeout
  File "/usr/local/lib/python3.6/dist-packages/urllib3/connectionpool.py", line 725, in urlopen
    method, url, error=e, _pool=self, _stacktrace=sys.exc_info()[2]
  File "/usr/local/lib/python3.6/dist-packages/urllib3/util/retry.py", line 439, in increment
    raise MaxRetryError(_pool, url, error or ResponseError(cause))
urllib3.exceptions.MaxRetryError: HTTPConnectionPool(host='172.17.0.1', port=8080): Max retries exceeded with url: /judge_server/heartbeat (Caused by NewConnectionError('<urllib3.connection.HTTPConnection object at 0x7ff3054e0ac8>: Failed to establish a new connection: [Errno 111] Connection refused',))

During handling of the above exception, another exception occurred:

Traceback (most recent call last):
  File "/code/service.py", line 19, in _request
    "Content-Type": "application/json"}, timeout=5).text
  File "/usr/local/lib/python3.6/dist-packages/requests/api.py", line 119, in post
    return request('post', url, data=data, json=json, **kwargs)
  File "/usr/local/lib/python3.6/dist-packages/requests/api.py", line 61, in request
    return session.request(method=method, url=url, **kwargs)
  File "/usr/local/lib/python3.6/dist-packages/requests/sessions.py", line 530, in request
    resp = self.send(prep, **send_kwargs)
  File "/usr/local/lib/python3.6/dist-packages/requests/sessions.py", line 643, in send
    r = adapter.send(request, **kwargs)
  File "/usr/local/lib/python3.6/dist-packages/requests/adapters.py", line 516, in send
    raise ConnectionError(e, request=request)
requests.exceptions.ConnectionError: HTTPConnectionPool(host='172.17.0.1', port=8080): Max retries exceeded with url: /judge_server/heartbeat (Caused by NewConnectionError('<urllib3.connection.HTTPConnection object at 0x7ff3054e0ac8>: Failed to establish a new connection: [Errno 111] Connection refused',))
2020-11-07 07:59:56,716 ERROR 
Traceback (most recent call last):
  File "/usr/local/lib/python3.6/dist-packages/urllib3/connection.py", line 160, in _new_conn
    (self._dns_host, self.port), self.timeout, **extra_kw
  File "/usr/local/lib/python3.6/dist-packages/urllib3/util/connection.py", line 84, in create_connection
    raise err
  File "/usr/local/lib/python3.6/dist-packages/urllib3/util/connection.py", line 74, in create_connection
    sock.connect(sa)
ConnectionRefusedError: [Errno 111] Connection refused

During handling of the above exception, another exception occurred:

Traceback (most recent call last):
  File "/usr/local/lib/python3.6/dist-packages/urllib3/connectionpool.py", line 677, in urlopen
    chunked=chunked,
  File "/usr/local/lib/python3.6/dist-packages/urllib3/connectionpool.py", line 392, in _make_request
    conn.request(method, url, **httplib_request_kw)
  File "/usr/lib/python3.6/http/client.py", line 1264, in request
    self._send_request(method, url, body, headers, encode_chunked)
  File "/usr/lib/python3.6/http/client.py", line 1310, in _send_request
    self.endheaders(body, encode_chunked=encode_chunked)
  File "/usr/lib/python3.6/http/client.py", line 1259, in endheaders
    self._send_output(message_body, encode_chunked=encode_chunked)
  File "/usr/lib/python3.6/http/client.py", line 1038, in _send_output
    self.send(msg)
  File "/usr/lib/python3.6/http/client.py", line 976, in send
    self.connect()
  File "/usr/local/lib/python3.6/dist-packages/urllib3/connection.py", line 187, in connect
    conn = self._new_conn()
  File "/usr/local/lib/python3.6/dist-packages/urllib3/connection.py", line 172, in _new_conn
    self, "Failed to establish a new connection: %s" % e
urllib3.exceptions.NewConnectionError: <urllib3.connection.HTTPConnection object at 0x7ff3054e0ac8>: Failed to establish a new connection: [Errno 111] Connection refused

During handling of the above exception, another exception occurred:

Traceback (most recent call last):
  File "/usr/local/lib/python3.6/dist-packages/requests/adapters.py", line 449, in send
    timeout=timeout
  File "/usr/local/lib/python3.6/dist-packages/urllib3/connectionpool.py", line 725, in urlopen
    method, url, error=e, _pool=self, _stacktrace=sys.exc_info()[2]
  File "/usr/local/lib/python3.6/dist-packages/urllib3/util/retry.py", line 439, in increment
    raise MaxRetryError(_pool, url, error or ResponseError(cause))
urllib3.exceptions.MaxRetryError: HTTPConnectionPool(host='172.17.0.1', port=8080): Max retries exceeded with url: /judge_server/heartbeat (Caused by NewConnectionError('<urllib3.connection.HTTPConnection object at 0x7ff3054e0ac8>: Failed to establish a new connection: [Errno 111] Connection refused',))

During handling of the above exception, another exception occurred:

Traceback (most recent call last):
  File "/code/service.py", line 19, in _request
    "Content-Type": "application/json"}, timeout=5).text
  File "/usr/local/lib/python3.6/dist-packages/requests/api.py", line 119, in post
    return request('post', url, data=data, json=json, **kwargs)
  File "/usr/local/lib/python3.6/dist-packages/requests/api.py", line 61, in request
    return session.request(method=method, url=url, **kwargs)
  File "/usr/local/lib/python3.6/dist-packages/requests/sessions.py", line 530, in request
    resp = self.send(prep, **send_kwargs)
  File "/usr/local/lib/python3.6/dist-packages/requests/sessions.py", line 643, in send
    r = adapter.send(request, **kwargs)
  File "/usr/local/lib/python3.6/dist-packages/requests/adapters.py", line 516, in send
    raise ConnectionError(e, request=request)
requests.exceptions.ConnectionError: HTTPConnectionPool(host='172.17.0.1', port=8080): Max retries exceeded with url: /judge_server/heartbeat (Caused by NewConnectionError('<urllib3.connection.HTTPConnection object at 0x7ff3054e0ac8>: Failed to establish a new connection: [Errno 111] Connection refused',))

During handling of the above exception, another exception occurred:

Traceback (most recent call last):
  File "/code/service.py", line 42, in <module>
    service.heartbeat()
  File "/code/service.py", line 35, in heartbeat
    self._request(data)
  File "/code/service.py", line 22, in _request
    raise JudgeServiceError("Heartbeat request failed")
exception.JudgeServiceError
2020-11-07 08:00:01,888 ERROR HTTPConnectionPool(host='172.17.0.1', port=8080): Max retries exceeded with url: /judge_server/heartbeat (Caused by NewConnectionError('<urllib3.connection.HTTPConnection object at 0x7f0981003a90>: Failed to establish a new connection: [Errno 111] Connection refused',))
Traceback (most recent call last):
  File "/usr/local/lib/python3.6/dist-packages/urllib3/connection.py", line 160, in _new_conn
    (self._dns_host, self.port), self.timeout, **extra_kw
  File "/usr/local/lib/python3.6/dist-packages/urllib3/util/connection.py", line 84, in create_connection
    raise err
  File "/usr/local/lib/python3.6/dist-packages/urllib3/util/connection.py", line 74, in create_connection
    sock.connect(sa)
ConnectionRefusedError: [Errno 111] Connection refused

During handling of the above exception, another exception occurred:

Traceback (most recent call last):
  File "/usr/local/lib/python3.6/dist-packages/urllib3/connectionpool.py", line 677, in urlopen
    chunked=chunked,
  File "/usr/local/lib/python3.6/dist-packages/urllib3/connectionpool.py", line 392, in _make_request
    conn.request(method, url, **httplib_request_kw)
  File "/usr/lib/python3.6/http/client.py", line 1264, in request
    self._send_request(method, url, body, headers, encode_chunked)
  File "/usr/lib/python3.6/http/client.py", line 1310, in _send_request
    self.endheaders(body, encode_chunked=encode_chunked)
  File "/usr/lib/python3.6/http/client.py", line 1259, in endheaders
    self._send_output(message_body, encode_chunked=encode_chunked)
  File "/usr/lib/python3.6/http/client.py", line 1038, in _send_output
    self.send(msg)
  File "/usr/lib/python3.6/http/client.py", line 976, in send
    self.connect()
  File "/usr/local/lib/python3.6/dist-packages/urllib3/connection.py", line 187, in connect
    conn = self._new_conn()
  File "/usr/local/lib/python3.6/dist-packages/urllib3/connection.py", line 172, in _new_conn
    self, "Failed to establish a new connection: %s" % e
urllib3.exceptions.NewConnectionError: <urllib3.connection.HTTPConnection object at 0x7f0981003a90>: Failed to establish a new connection: [Errno 111] Connection refused

During handling of the above exception, another exception occurred:

Traceback (most recent call last):
  File "/usr/local/lib/python3.6/dist-packages/requests/adapters.py", line 449, in send
    timeout=timeout
  File "/usr/local/lib/python3.6/dist-packages/urllib3/connectionpool.py", line 725, in urlopen
    method, url, error=e, _pool=self, _stacktrace=sys.exc_info()[2]
  File "/usr/local/lib/python3.6/dist-packages/urllib3/util/retry.py", line 439, in increment
    raise MaxRetryError(_pool, url, error or ResponseError(cause))
urllib3.exceptions.MaxRetryError: HTTPConnectionPool(host='172.17.0.1', port=8080): Max retries exceeded with url: /judge_server/heartbeat (Caused by NewConnectionError('<urllib3.connection.HTTPConnection object at 0x7f0981003a90>: Failed to establish a new connection: [Errno 111] Connection refused',))

During handling of the above exception, another exception occurred:

Traceback (most recent call last):
  File "/code/service.py", line 19, in _request
    "Content-Type": "application/json"}, timeout=5).text
  File "/usr/local/lib/python3.6/dist-packages/requests/api.py", line 119, in post
    return request('post', url, data=data, json=json, **kwargs)
  File "/usr/local/lib/python3.6/dist-packages/requests/api.py", line 61, in request
    return session.request(method=method, url=url, **kwargs)
  File "/usr/local/lib/python3.6/dist-packages/requests/sessions.py", line 530, in request
    resp = self.send(prep, **send_kwargs)
  File "/usr/local/lib/python3.6/dist-packages/requests/sessions.py", line 643, in send
    r = adapter.send(request, **kwargs)
  File "/usr/local/lib/python3.6/dist-packages/requests/adapters.py", line 516, in send
    raise ConnectionError(e, request=request)
requests.exceptions.ConnectionError: HTTPConnectionPool(host='172.17.0.1', port=8080): Max retries exceeded with url: /judge_server/heartbeat (Caused by NewConnectionError('<urllib3.connection.HTTPConnection object at 0x7f0981003a90>: Failed to establish a new connection: [Errno 111] Connection refused',))
2020-11-07 08:00:01,889 ERROR 
Traceback (most recent call last):
  File "/usr/local/lib/python3.6/dist-packages/urllib3/connection.py", line 160, in _new_conn
    (self._dns_host, self.port), self.timeout, **extra_kw
  File "/usr/local/lib/python3.6/dist-packages/urllib3/util/connection.py", line 84, in create_connection
    raise err
  File "/usr/local/lib/python3.6/dist-packages/urllib3/util/connection.py", line 74, in create_connection
    sock.connect(sa)
ConnectionRefusedError: [Errno 111] Connection refused

During handling of the above exception, another exception occurred:

Traceback (most recent call last):
  File "/usr/local/lib/python3.6/dist-packages/urllib3/connectionpool.py", line 677, in urlopen
    chunked=chunked,
  File "/usr/local/lib/python3.6/dist-packages/urllib3/connectionpool.py", line 392, in _make_request
    conn.request(method, url, **httplib_request_kw)
  File "/usr/lib/python3.6/http/client.py", line 1264, in request
    self._send_request(method, url, body, headers, encode_chunked)
  File "/usr/lib/python3.6/http/client.py", line 1310, in _send_request
    self.endheaders(body, encode_chunked=encode_chunked)
  File "/usr/lib/python3.6/http/client.py", line 1259, in endheaders
    self._send_output(message_body, encode_chunked=encode_chunked)
  File "/usr/lib/python3.6/http/client.py", line 1038, in _send_output
    self.send(msg)
  File "/usr/lib/python3.6/http/client.py", line 976, in send
    self.connect()
  File "/usr/local/lib/python3.6/dist-packages/urllib3/connection.py", line 187, in connect
    conn = self._new_conn()
  File "/usr/local/lib/python3.6/dist-packages/urllib3/connection.py", line 172, in _new_conn
    self, "Failed to establish a new connection: %s" % e
urllib3.exceptions.NewConnectionError: <urllib3.connection.HTTPConnection object at 0x7f0981003a90>: Failed to establish a new connection: [Errno 111] Connection refused

During handling of the above exception, another exception occurred:

Traceback (most recent call last):
  File "/usr/local/lib/python3.6/dist-packages/requests/adapters.py", line 449, in send
    timeout=timeout
  File "/usr/local/lib/python3.6/dist-packages/urllib3/connectionpool.py", line 725, in urlopen
    method, url, error=e, _pool=self, _stacktrace=sys.exc_info()[2]
  File "/usr/local/lib/python3.6/dist-packages/urllib3/util/retry.py", line 439, in increment
    raise MaxRetryError(_pool, url, error or ResponseError(cause))
urllib3.exceptions.MaxRetryError: HTTPConnectionPool(host='172.17.0.1', port=8080): Max retries exceeded with url: /judge_server/heartbeat (Caused by NewConnectionError('<urllib3.connection.HTTPConnection object at 0x7f0981003a90>: Failed to establish a new connection: [Errno 111] Connection refused',))

During handling of the above exception, another exception occurred:

Traceback (most recent call last):
  File "/code/service.py", line 19, in _request
    "Content-Type": "application/json"}, timeout=5).text
  File "/usr/local/lib/python3.6/dist-packages/requests/api.py", line 119, in post
    return request('post', url, data=data, json=json, **kwargs)
  File "/usr/local/lib/python3.6/dist-packages/requests/api.py", line 61, in request
    return session.request(method=method, url=url, **kwargs)
  File "/usr/local/lib/python3.6/dist-packages/requests/sessions.py", line 530, in request
    resp = self.send(prep, **send_kwargs)
  File "/usr/local/lib/python3.6/dist-packages/requests/sessions.py", line 643, in send
    r = adapter.send(request, **kwargs)
  File "/usr/local/lib/python3.6/dist-packages/requests/adapters.py", line 516, in send
    raise ConnectionError(e, request=request)
requests.exceptions.ConnectionError: HTTPConnectionPool(host='172.17.0.1', port=8080): Max retries exceeded with url: /judge_server/heartbeat (Caused by NewConnectionError('<urllib3.connection.HTTPConnection object at 0x7f0981003a90>: Failed to establish a new connection: [Errno 111] Connection refused',))

During handling of the above exception, another exception occurred:

Traceback (most recent call last):
  File "/code/service.py", line 42, in <module>
    service.heartbeat()
  File "/code/service.py", line 35, in heartbeat
    self._request(data)
  File "/code/service.py", line 22, in _request
    raise JudgeServiceError("Heartbeat request failed")
exception.JudgeServiceError
2020-11-07 08:00:07,054 ERROR HTTPConnectionPool(host='172.17.0.1', port=8080): Max retries exceeded with url: /judge_server/heartbeat (Caused by NewConnectionError('<urllib3.connection.HTTPConnection object at 0x7f92d2746a20>: Failed to establish a new connection: [Errno 111] Connection refused',))
Traceback (most recent call last):
  File "/usr/local/lib/python3.6/dist-packages/urllib3/connection.py", line 160, in _new_conn
    (self._dns_host, self.port), self.timeout, **extra_kw
  File "/usr/local/lib/python3.6/dist-packages/urllib3/util/connection.py", line 84, in create_connection
    raise err
  File "/usr/local/lib/python3.6/dist-packages/urllib3/util/connection.py", line 74, in create_connection
    sock.connect(sa)
ConnectionRefusedError: [Errno 111] Connection refused

During handling of the above exception, another exception occurred:

Traceback (most recent call last):
  File "/usr/local/lib/python3.6/dist-packages/urllib3/connectionpool.py", line 677, in urlopen
    chunked=chunked,
  File "/usr/local/lib/python3.6/dist-packages/urllib3/connectionpool.py", line 392, in _make_request
    conn.request(method, url, **httplib_request_kw)
  File "/usr/lib/python3.6/http/client.py", line 1264, in request
    self._send_request(method, url, body, headers, encode_chunked)
  File "/usr/lib/python3.6/http/client.py", line 1310, in _send_request
    self.endheaders(body, encode_chunked=encode_chunked)
  File "/usr/lib/python3.6/http/client.py", line 1259, in endheaders
    self._send_output(message_body, encode_chunked=encode_chunked)
  File "/usr/lib/python3.6/http/client.py", line 1038, in _send_output
    self.send(msg)
  File "/usr/lib/python3.6/http/client.py", line 976, in send
    self.connect()
  File "/usr/local/lib/python3.6/dist-packages/urllib3/connection.py", line 187, in connect
    conn = self._new_conn()
  File "/usr/local/lib/python3.6/dist-packages/urllib3/connection.py", line 172, in _new_conn
    self, "Failed to establish a new connection: %s" % e
urllib3.exceptions.NewConnectionError: <urllib3.connection.HTTPConnection object at 0x7f92d2746a20>: Failed to establish a new connection: [Errno 111] Connection refused

During handling of the above exception, another exception occurred:

Traceback (most recent call last):
  File "/usr/local/lib/python3.6/dist-packages/requests/adapters.py", line 449, in send
    timeout=timeout
  File "/usr/local/lib/python3.6/dist-packages/urllib3/connectionpool.py", line 725, in urlopen
    method, url, error=e, _pool=self, _stacktrace=sys.exc_info()[2]
  File "/usr/local/lib/python3.6/dist-packages/urllib3/util/retry.py", line 439, in increment
    raise MaxRetryError(_pool, url, error or ResponseError(cause))
urllib3.exceptions.MaxRetryError: HTTPConnectionPool(host='172.17.0.1', port=8080): Max retries exceeded with url: /judge_server/heartbeat (Caused by NewConnectionError('<urllib3.connection.HTTPConnection object at 0x7f92d2746a20>: Failed to establish a new connection: [Errno 111] Connection refused',))

During handling of the above exception, another exception occurred:

Traceback (most recent call last):
  File "/code/service.py", line 19, in _request
    "Content-Type": "application/json"}, timeout=5).text
  File "/usr/local/lib/python3.6/dist-packages/requests/api.py", line 119, in post
    return request('post', url, data=data, json=json, **kwargs)
  File "/usr/local/lib/python3.6/dist-packages/requests/api.py", line 61, in request
    return session.request(method=method, url=url, **kwargs)
  File "/usr/local/lib/python3.6/dist-packages/requests/sessions.py", line 530, in request
    resp = self.send(prep, **send_kwargs)
  File "/usr/local/lib/python3.6/dist-packages/requests/sessions.py", line 643, in send
    r = adapter.send(request, **kwargs)
  File "/usr/local/lib/python3.6/dist-packages/requests/adapters.py", line 516, in send
    raise ConnectionError(e, request=request)
requests.exceptions.ConnectionError: HTTPConnectionPool(host='172.17.0.1', port=8080): Max retries exceeded with url: /judge_server/heartbeat (Caused by NewConnectionError('<urllib3.connection.HTTPConnection object at 0x7f92d2746a20>: Failed to establish a new connection: [Errno 111] Connection refused',))
2020-11-07 08:00:07,055 ERROR 
Traceback (most recent call last):
  File "/usr/local/lib/python3.6/dist-packages/urllib3/connection.py", line 160, in _new_conn
    (self._dns_host, self.port), self.timeout, **extra_kw
  File "/usr/local/lib/python3.6/dist-packages/urllib3/util/connection.py", line 84, in create_connection
    raise err
  File "/usr/local/lib/python3.6/dist-packages/urllib3/util/connection.py", line 74, in create_connection
    sock.connect(sa)
ConnectionRefusedError: [Errno 111] Connection refused

During handling of the above exception, another exception occurred:

Traceback (most recent call last):
  File "/usr/local/lib/python3.6/dist-packages/urllib3/connectionpool.py", line 677, in urlopen
    chunked=chunked,
  File "/usr/local/lib/python3.6/dist-packages/urllib3/connectionpool.py", line 392, in _make_request
    conn.request(method, url, **httplib_request_kw)
  File "/usr/lib/python3.6/http/client.py", line 1264, in request
    self._send_request(method, url, body, headers, encode_chunked)
  File "/usr/lib/python3.6/http/client.py", line 1310, in _send_request
    self.endheaders(body, encode_chunked=encode_chunked)
  File "/usr/lib/python3.6/http/client.py", line 1259, in endheaders
    self._send_output(message_body, encode_chunked=encode_chunked)
  File "/usr/lib/python3.6/http/client.py", line 1038, in _send_output
    self.send(msg)
  File "/usr/lib/python3.6/http/client.py", line 976, in send
    self.connect()
  File "/usr/local/lib/python3.6/dist-packages/urllib3/connection.py", line 187, in connect
    conn = self._new_conn()
  File "/usr/local/lib/python3.6/dist-packages/urllib3/connection.py", line 172, in _new_conn
    self, "Failed to establish a new connection: %s" % e
urllib3.exceptions.NewConnectionError: <urllib3.connection.HTTPConnection object at 0x7f92d2746a20>: Failed to establish a new connection: [Errno 111] Connection refused

During handling of the above exception, another exception occurred:

Traceback (most recent call last):
  File "/usr/local/lib/python3.6/dist-packages/requests/adapters.py", line 449, in send
    timeout=timeout
  File "/usr/local/lib/python3.6/dist-packages/urllib3/connectionpool.py", line 725, in urlopen
    method, url, error=e, _pool=self, _stacktrace=sys.exc_info()[2]
  File "/usr/local/lib/python3.6/dist-packages/urllib3/util/retry.py", line 439, in increment
    raise MaxRetryError(_pool, url, error or ResponseError(cause))
urllib3.exceptions.MaxRetryError: HTTPConnectionPool(host='172.17.0.1', port=8080): Max retries exceeded with url: /judge_server/heartbeat (Caused by NewConnectionError('<urllib3.connection.HTTPConnection object at 0x7f92d2746a20>: Failed to establish a new connection: [Errno 111] Connection refused',))

During handling of the above exception, another exception occurred:

Traceback (most recent call last):
  File "/code/service.py", line 19, in _request
    "Content-Type": "application/json"}, timeout=5).text
  File "/usr/local/lib/python3.6/dist-packages/requests/api.py", line 119, in post
    return request('post', url, data=data, json=json, **kwargs)
  File "/usr/local/lib/python3.6/dist-packages/requests/api.py", line 61, in request
    return session.request(method=method, url=url, **kwargs)
  File "/usr/local/lib/python3.6/dist-packages/requests/sessions.py", line 530, in request
    resp = self.send(prep, **send_kwargs)
  File "/usr/local/lib/python3.6/dist-packages/requests/sessions.py", line 643, in send
    r = adapter.send(request, **kwargs)
  File "/usr/local/lib/python3.6/dist-packages/requests/adapters.py", line 516, in send
    raise ConnectionError(e, request=request)
requests.exceptions.ConnectionError: HTTPConnectionPool(host='172.17.0.1', port=8080): Max retries exceeded with url: /judge_server/heartbeat (Caused by NewConnectionError('<urllib3.connection.HTTPConnection object at 0x7f92d2746a20>: Failed to establish a new connection: [Errno 111] Connection refused',))

During handling of the above exception, another exception occurred:

Traceback (most recent call last):
  File "/code/service.py", line 42, in <module>
    service.heartbeat()
  File "/code/service.py", line 35, in heartbeat
    self._request(data)
  File "/code/service.py", line 22, in _request
    raise JudgeServiceError("Heartbeat request failed")
exception.JudgeServiceError
2020-11-07 08:00:12,225 ERROR HTTPConnectionPool(host='172.17.0.1', port=8080): Max retries exceeded with url: /judge_server/heartbeat (Caused by NewConnectionError('<urllib3.connection.HTTPConnection object at 0x7f53704a4a20>: Failed to establish a new connection: [Errno 111] Connection refused',))
Traceback (most recent call last):
  File "/usr/local/lib/python3.6/dist-packages/urllib3/connection.py", line 160, in _new_conn
    (self._dns_host, self.port), self.timeout, **extra_kw
  File "/usr/local/lib/python3.6/dist-packages/urllib3/util/connection.py", line 84, in create_connection
    raise err
  File "/usr/local/lib/python3.6/dist-packages/urllib3/util/connection.py", line 74, in create_connection
    sock.connect(sa)
ConnectionRefusedError: [Errno 111] Connection refused

During handling of the above exception, another exception occurred:

Traceback (most recent call last):
  File "/usr/local/lib/python3.6/dist-packages/urllib3/connectionpool.py", line 677, in urlopen
    chunked=chunked,
  File "/usr/local/lib/python3.6/dist-packages/urllib3/connectionpool.py", line 392, in _make_request
    conn.request(method, url, **httplib_request_kw)
  File "/usr/lib/python3.6/http/client.py", line 1264, in request
    self._send_request(method, url, body, headers, encode_chunked)
  File "/usr/lib/python3.6/http/client.py", line 1310, in _send_request
    self.endheaders(body, encode_chunked=encode_chunked)
  File "/usr/lib/python3.6/http/client.py", line 1259, in endheaders
    self._send_output(message_body, encode_chunked=encode_chunked)
  File "/usr/lib/python3.6/http/client.py", line 1038, in _send_output
    self.send(msg)
  File "/usr/lib/python3.6/http/client.py", line 976, in send
    self.connect()
  File "/usr/local/lib/python3.6/dist-packages/urllib3/connection.py", line 187, in connect
    conn = self._new_conn()
  File "/usr/local/lib/python3.6/dist-packages/urllib3/connection.py", line 172, in _new_conn
    self, "Failed to establish a new connection: %s" % e
urllib3.exceptions.NewConnectionError: <urllib3.connection.HTTPConnection object at 0x7f53704a4a20>: Failed to establish a new connection: [Errno 111] Connection refused

During handling of the above exception, another exception occurred:

Traceback (most recent call last):
  File "/usr/local/lib/python3.6/dist-packages/requests/adapters.py", line 449, in send
    timeout=timeout
  File "/usr/local/lib/python3.6/dist-packages/urllib3/connectionpool.py", line 725, in urlopen
    method, url, error=e, _pool=self, _stacktrace=sys.exc_info()[2]
  File "/usr/local/lib/python3.6/dist-packages/urllib3/util/retry.py", line 439, in increment
    raise MaxRetryError(_pool, url, error or ResponseError(cause))
urllib3.exceptions.MaxRetryError: HTTPConnectionPool(host='172.17.0.1', port=8080): Max retries exceeded with url: /judge_server/heartbeat (Caused by NewConnectionError('<urllib3.connection.HTTPConnection object at 0x7f53704a4a20>: Failed to establish a new connection: [Errno 111] Connection refused',))

During handling of the above exception, another exception occurred:

Traceback (most recent call last):
  File "/code/service.py", line 19, in _request
    "Content-Type": "application/json"}, timeout=5).text
  File "/usr/local/lib/python3.6/dist-packages/requests/api.py", line 119, in post
    return request('post', url, data=data, json=json, **kwargs)
  File "/usr/local/lib/python3.6/dist-packages/requests/api.py", line 61, in request
    return session.request(method=method, url=url, **kwargs)
  File "/usr/local/lib/python3.6/dist-packages/requests/sessions.py", line 530, in request
    resp = self.send(prep, **send_kwargs)
  File "/usr/local/lib/python3.6/dist-packages/requests/sessions.py", line 643, in send
    r = adapter.send(request, **kwargs)
  File "/usr/local/lib/python3.6/dist-packages/requests/adapters.py", line 516, in send
    raise ConnectionError(e, request=request)
requests.exceptions.ConnectionError: HTTPConnectionPool(host='172.17.0.1', port=8080): Max retries exceeded with url: /judge_server/heartbeat (Caused by NewConnectionError('<urllib3.connection.HTTPConnection object at 0x7f53704a4a20>: Failed to establish a new connection: [Errno 111] Connection refused',))
2020-11-07 08:00:12,226 ERROR 
Traceback (most recent call last):
  File "/usr/local/lib/python3.6/dist-packages/urllib3/connection.py", line 160, in _new_conn
    (self._dns_host, self.port), self.timeout, **extra_kw
  File "/usr/local/lib/python3.6/dist-packages/urllib3/util/connection.py", line 84, in create_connection
    raise err
  File "/usr/local/lib/python3.6/dist-packages/urllib3/util/connection.py", line 74, in create_connection
    sock.connect(sa)
ConnectionRefusedError: [Errno 111] Connection refused

During handling of the above exception, another exception occurred:

Traceback (most recent call last):
  File "/usr/local/lib/python3.6/dist-packages/urllib3/connectionpool.py", line 677, in urlopen
    chunked=chunked,
  File "/usr/local/lib/python3.6/dist-packages/urllib3/connectionpool.py", line 392, in _make_request
    conn.request(method, url, **httplib_request_kw)
  File "/usr/lib/python3.6/http/client.py", line 1264, in request
    self._send_request(method, url, body, headers, encode_chunked)
  File "/usr/lib/python3.6/http/client.py", line 1310, in _send_request
    self.endheaders(body, encode_chunked=encode_chunked)
  File "/usr/lib/python3.6/http/client.py", line 1259, in endheaders
    self._send_output(message_body, encode_chunked=encode_chunked)
  File "/usr/lib/python3.6/http/client.py", line 1038, in _send_output
    self.send(msg)
  File "/usr/lib/python3.6/http/client.py", line 976, in send
    self.connect()
  File "/usr/local/lib/python3.6/dist-packages/urllib3/connection.py", line 187, in connect
    conn = self._new_conn()
  File "/usr/local/lib/python3.6/dist-packages/urllib3/connection.py", line 172, in _new_conn
    self, "Failed to establish a new connection: %s" % e
urllib3.exceptions.NewConnectionError: <urllib3.connection.HTTPConnection object at 0x7f53704a4a20>: Failed to establish a new connection: [Errno 111] Connection refused

During handling of the above exception, another exception occurred:

Traceback (most recent call last):
  File "/usr/local/lib/python3.6/dist-packages/requests/adapters.py", line 449, in send
    timeout=timeout
  File "/usr/local/lib/python3.6/dist-packages/urllib3/connectionpool.py", line 725, in urlopen
    method, url, error=e, _pool=self, _stacktrace=sys.exc_info()[2]
  File "/usr/local/lib/python3.6/dist-packages/urllib3/util/retry.py", line 439, in increment
    raise MaxRetryError(_pool, url, error or ResponseError(cause))
urllib3.exceptions.MaxRetryError: HTTPConnectionPool(host='172.17.0.1', port=8080): Max retries exceeded with url: /judge_server/heartbeat (Caused by NewConnectionError('<urllib3.connection.HTTPConnection object at 0x7f53704a4a20>: Failed to establish a new connection: [Errno 111] Connection refused',))

During handling of the above exception, another exception occurred:

Traceback (most recent call last):
  File "/code/service.py", line 19, in _request
    "Content-Type": "application/json"}, timeout=5).text
  File "/usr/local/lib/python3.6/dist-packages/requests/api.py", line 119, in post
    return request('post', url, data=data, json=json, **kwargs)
  File "/usr/local/lib/python3.6/dist-packages/requests/api.py", line 61, in request
    return session.request(method=method, url=url, **kwargs)
  File "/usr/local/lib/python3.6/dist-packages/requests/sessions.py", line 530, in request
    resp = self.send(prep, **send_kwargs)
  File "/usr/local/lib/python3.6/dist-packages/requests/sessions.py", line 643, in send
    r = adapter.send(request, **kwargs)
  File "/usr/local/lib/python3.6/dist-packages/requests/adapters.py", line 516, in send
    raise ConnectionError(e, request=request)
requests.exceptions.ConnectionError: HTTPConnectionPool(host='172.17.0.1', port=8080): Max retries exceeded with url: /judge_server/heartbeat (Caused by NewConnectionError('<urllib3.connection.HTTPConnection object at 0x7f53704a4a20>: Failed to establish a new connection: [Errno 111] Connection refused',))

During handling of the above exception, another exception occurred:

Traceback (most recent call last):
  File "/code/service.py", line 42, in <module>
    service.heartbeat()
  File "/code/service.py", line 35, in heartbeat
    self._request(data)
  File "/code/service.py", line 22, in _request
    raise JudgeServiceError("Heartbeat request failed")
exception.JudgeServiceError
2020-11-07 08:00:17,398 ERROR HTTPConnectionPool(host='172.17.0.1', port=8080): Max retries exceeded with url: /judge_server/heartbeat (Caused by NewConnectionError('<urllib3.connection.HTTPConnection object at 0x7f9257baea20>: Failed to establish a new connection: [Errno 111] Connection refused',))
Traceback (most recent call last):
  File "/usr/local/lib/python3.6/dist-packages/urllib3/connection.py", line 160, in _new_conn
    (self._dns_host, self.port), self.timeout, **extra_kw
  File "/usr/local/lib/python3.6/dist-packages/urllib3/util/connection.py", line 84, in create_connection
    raise err
  File "/usr/local/lib/python3.6/dist-packages/urllib3/util/connection.py", line 74, in create_connection
    sock.connect(sa)
ConnectionRefusedError: [Errno 111] Connection refused

During handling of the above exception, another exception occurred:

Traceback (most recent call last):
  File "/usr/local/lib/python3.6/dist-packages/urllib3/connectionpool.py", line 677, in urlopen
    chunked=chunked,
  File "/usr/local/lib/python3.6/dist-packages/urllib3/connectionpool.py", line 392, in _make_request
    conn.request(method, url, **httplib_request_kw)
  File "/usr/lib/python3.6/http/client.py", line 1264, in request
    self._send_request(method, url, body, headers, encode_chunked)
  File "/usr/lib/python3.6/http/client.py", line 1310, in _send_request
    self.endheaders(body, encode_chunked=encode_chunked)
  File "/usr/lib/python3.6/http/client.py", line 1259, in endheaders
    self._send_output(message_body, encode_chunked=encode_chunked)
  File "/usr/lib/python3.6/http/client.py", line 1038, in _send_output
    self.send(msg)
  File "/usr/lib/python3.6/http/client.py", line 976, in send
    self.connect()
  File "/usr/local/lib/python3.6/dist-packages/urllib3/connection.py", line 187, in connect
    conn = self._new_conn()
  File "/usr/local/lib/python3.6/dist-packages/urllib3/connection.py", line 172, in _new_conn
    self, "Failed to establish a new connection: %s" % e
urllib3.exceptions.NewConnectionError: <urllib3.connection.HTTPConnection object at 0x7f9257baea20>: Failed to establish a new connection: [Errno 111] Connection refused

During handling of the above exception, another exception occurred:

Traceback (most recent call last):
  File "/usr/local/lib/python3.6/dist-packages/requests/adapters.py", line 449, in send
    timeout=timeout
  File "/usr/local/lib/python3.6/dist-packages/urllib3/connectionpool.py", line 725, in urlopen
    method, url, error=e, _pool=self, _stacktrace=sys.exc_info()[2]
  File "/usr/local/lib/python3.6/dist-packages/urllib3/util/retry.py", line 439, in increment
    raise MaxRetryError(_pool, url, error or ResponseError(cause))
urllib3.exceptions.MaxRetryError: HTTPConnectionPool(host='172.17.0.1', port=8080): Max retries exceeded with url: /judge_server/heartbeat (Caused by NewConnectionError('<urllib3.connection.HTTPConnection object at 0x7f9257baea20>: Failed to establish a new connection: [Errno 111] Connection refused',))

During handling of the above exception, another exception occurred:

Traceback (most recent call last):
  File "/code/service.py", line 19, in _request
    "Content-Type": "application/json"}, timeout=5).text
  File "/usr/local/lib/python3.6/dist-packages/requests/api.py", line 119, in post
    return request('post', url, data=data, json=json, **kwargs)
  File "/usr/local/lib/python3.6/dist-packages/requests/api.py", line 61, in request
    return session.request(method=method, url=url, **kwargs)
  File "/usr/local/lib/python3.6/dist-packages/requests/sessions.py", line 530, in request
    resp = self.send(prep, **send_kwargs)
  File "/usr/local/lib/python3.6/dist-packages/requests/sessions.py", line 643, in send
    r = adapter.send(request, **kwargs)
  File "/usr/local/lib/python3.6/dist-packages/requests/adapters.py", line 516, in send
    raise ConnectionError(e, request=request)
requests.exceptions.ConnectionError: HTTPConnectionPool(host='172.17.0.1', port=8080): Max retries exceeded with url: /judge_server/heartbeat (Caused by NewConnectionError('<urllib3.connection.HTTPConnection object at 0x7f9257baea20>: Failed to establish a new connection: [Errno 111] Connection refused',))
2020-11-07 08:00:17,399 ERROR 
Traceback (most recent call last):
  File "/usr/local/lib/python3.6/dist-packages/urllib3/connection.py", line 160, in _new_conn
    (self._dns_host, self.port), self.timeout, **extra_kw
  File "/usr/local/lib/python3.6/dist-packages/urllib3/util/connection.py", line 84, in create_connection
    raise err
  File "/usr/local/lib/python3.6/dist-packages/urllib3/util/connection.py", line 74, in create_connection
    sock.connect(sa)
ConnectionRefusedError: [Errno 111] Connection refused

During handling of the above exception, another exception occurred:

Traceback (most recent call last):
  File "/usr/local/lib/python3.6/dist-packages/urllib3/connectionpool.py", line 677, in urlopen
    chunked=chunked,
  File "/usr/local/lib/python3.6/dist-packages/urllib3/connectionpool.py", line 392, in _make_request
    conn.request(method, url, **httplib_request_kw)
  File "/usr/lib/python3.6/http/client.py", line 1264, in request
    self._send_request(method, url, body, headers, encode_chunked)
  File "/usr/lib/python3.6/http/client.py", line 1310, in _send_request
    self.endheaders(body, encode_chunked=encode_chunked)
  File "/usr/lib/python3.6/http/client.py", line 1259, in endheaders
    self._send_output(message_body, encode_chunked=encode_chunked)
  File "/usr/lib/python3.6/http/client.py", line 1038, in _send_output
    self.send(msg)
  File "/usr/lib/python3.6/http/client.py", line 976, in send
    self.connect()
  File "/usr/local/lib/python3.6/dist-packages/urllib3/connection.py", line 187, in connect
    conn = self._new_conn()
  File "/usr/local/lib/python3.6/dist-packages/urllib3/connection.py", line 172, in _new_conn
    self, "Failed to establish a new connection: %s" % e
urllib3.exceptions.NewConnectionError: <urllib3.connection.HTTPConnection object at 0x7f9257baea20>: Failed to establish a new connection: [Errno 111] Connection refused

During handling of the above exception, another exception occurred:

Traceback (most recent call last):
  File "/usr/local/lib/python3.6/dist-packages/requests/adapters.py", line 449, in send
    timeout=timeout
  File "/usr/local/lib/python3.6/dist-packages/urllib3/connectionpool.py", line 725, in urlopen
    method, url, error=e, _pool=self, _stacktrace=sys.exc_info()[2]
  File "/usr/local/lib/python3.6/dist-packages/urllib3/util/retry.py", line 439, in increment
    raise MaxRetryError(_pool, url, error or ResponseError(cause))
urllib3.exceptions.MaxRetryError: HTTPConnectionPool(host='172.17.0.1', port=8080): Max retries exceeded with url: /judge_server/heartbeat (Caused by NewConnectionError('<urllib3.connection.HTTPConnection object at 0x7f9257baea20>: Failed to establish a new connection: [Errno 111] Connection refused',))

During handling of the above exception, another exception occurred:

Traceback (most recent call last):
  File "/code/service.py", line 19, in _request
    "Content-Type": "application/json"}, timeout=5).text
  File "/usr/local/lib/python3.6/dist-packages/requests/api.py", line 119, in post
    return request('post', url, data=data, json=json, **kwargs)
  File "/usr/local/lib/python3.6/dist-packages/requests/api.py", line 61, in request
    return session.request(method=method, url=url, **kwargs)
  File "/usr/local/lib/python3.6/dist-packages/requests/sessions.py", line 530, in request
    resp = self.send(prep, **send_kwargs)
  File "/usr/local/lib/python3.6/dist-packages/requests/sessions.py", line 643, in send
    r = adapter.send(request, **kwargs)
  File "/usr/local/lib/python3.6/dist-packages/requests/adapters.py", line 516, in send
    raise ConnectionError(e, request=request)
requests.exceptions.ConnectionError: HTTPConnectionPool(host='172.17.0.1', port=8080): Max retries exceeded with url: /judge_server/heartbeat (Caused by NewConnectionError('<urllib3.connection.HTTPConnection object at 0x7f9257baea20>: Failed to establish a new connection: [Errno 111] Connection refused',))

During handling of the above exception, another exception occurred:

Traceback (most recent call last):
  File "/code/service.py", line 42, in <module>
    service.heartbeat()
  File "/code/service.py", line 35, in heartbeat
    self._request(data)
  File "/code/service.py", line 22, in _request
    raise JudgeServiceError("Heartbeat request failed")
exception.JudgeServiceError
2020-11-07 08:00:22,562 ERROR HTTPConnectionPool(host='172.17.0.1', port=8080): Max retries exceeded with url: /judge_server/heartbeat (Caused by NewConnectionError('<urllib3.connection.HTTPConnection object at 0x7f6a0d23ba20>: Failed to establish a new connection: [Errno 111] Connection refused',))
Traceback (most recent call last):
  File "/usr/local/lib/python3.6/dist-packages/urllib3/connection.py", line 160, in _new_conn
    (self._dns_host, self.port), self.timeout, **extra_kw
  File "/usr/local/lib/python3.6/dist-packages/urllib3/util/connection.py", line 84, in create_connection
    raise err
  File "/usr/local/lib/python3.6/dist-packages/urllib3/util/connection.py", line 74, in create_connection
    sock.connect(sa)
ConnectionRefusedError: [Errno 111] Connection refused

During handling of the above exception, another exception occurred:

Traceback (most recent call last):
  File "/usr/local/lib/python3.6/dist-packages/urllib3/connectionpool.py", line 677, in urlopen
    chunked=chunked,
  File "/usr/local/lib/python3.6/dist-packages/urllib3/connectionpool.py", line 392, in _make_request
    conn.request(method, url, **httplib_request_kw)
  File "/usr/lib/python3.6/http/client.py", line 1264, in request
    self._send_request(method, url, body, headers, encode_chunked)
  File "/usr/lib/python3.6/http/client.py", line 1310, in _send_request
    self.endheaders(body, encode_chunked=encode_chunked)
  File "/usr/lib/python3.6/http/client.py", line 1259, in endheaders
    self._send_output(message_body, encode_chunked=encode_chunked)
  File "/usr/lib/python3.6/http/client.py", line 1038, in _send_output
    self.send(msg)
  File "/usr/lib/python3.6/http/client.py", line 976, in send
    self.connect()
  File "/usr/local/lib/python3.6/dist-packages/urllib3/connection.py", line 187, in connect
    conn = self._new_conn()
  File "/usr/local/lib/python3.6/dist-packages/urllib3/connection.py", line 172, in _new_conn
    self, "Failed to establish a new connection: %s" % e
urllib3.exceptions.NewConnectionError: <urllib3.connection.HTTPConnection object at 0x7f6a0d23ba20>: Failed to establish a new connection: [Errno 111] Connection refused

During handling of the above exception, another exception occurred:

Traceback (most recent call last):
  File "/usr/local/lib/python3.6/dist-packages/requests/adapters.py", line 449, in send
    timeout=timeout
  File "/usr/local/lib/python3.6/dist-packages/urllib3/connectionpool.py", line 725, in urlopen
    method, url, error=e, _pool=self, _stacktrace=sys.exc_info()[2]
  File "/usr/local/lib/python3.6/dist-packages/urllib3/util/retry.py", line 439, in increment
    raise MaxRetryError(_pool, url, error or ResponseError(cause))
urllib3.exceptions.MaxRetryError: HTTPConnectionPool(host='172.17.0.1', port=8080): Max retries exceeded with url: /judge_server/heartbeat (Caused by NewConnectionError('<urllib3.connection.HTTPConnection object at 0x7f6a0d23ba20>: Failed to establish a new connection: [Errno 111] Connection refused',))

During handling of the above exception, another exception occurred:

Traceback (most recent call last):
  File "/code/service.py", line 19, in _request
    "Content-Type": "application/json"}, timeout=5).text
  File "/usr/local/lib/python3.6/dist-packages/requests/api.py", line 119, in post
    return request('post', url, data=data, json=json, **kwargs)
  File "/usr/local/lib/python3.6/dist-packages/requests/api.py", line 61, in request
    return session.request(method=method, url=url, **kwargs)
  File "/usr/local/lib/python3.6/dist-packages/requests/sessions.py", line 530, in request
    resp = self.send(prep, **send_kwargs)
  File "/usr/local/lib/python3.6/dist-packages/requests/sessions.py", line 643, in send
    r = adapter.send(request, **kwargs)
  File "/usr/local/lib/python3.6/dist-packages/requests/adapters.py", line 516, in send
    raise ConnectionError(e, request=request)
requests.exceptions.ConnectionError: HTTPConnectionPool(host='172.17.0.1', port=8080): Max retries exceeded with url: /judge_server/heartbeat (Caused by NewConnectionError('<urllib3.connection.HTTPConnection object at 0x7f6a0d23ba20>: Failed to establish a new connection: [Errno 111] Connection refused',))
2020-11-07 08:00:22,563 ERROR 
Traceback (most recent call last):
  File "/usr/local/lib/python3.6/dist-packages/urllib3/connection.py", line 160, in _new_conn
    (self._dns_host, self.port), self.timeout, **extra_kw
  File "/usr/local/lib/python3.6/dist-packages/urllib3/util/connection.py", line 84, in create_connection
    raise err
  File "/usr/local/lib/python3.6/dist-packages/urllib3/util/connection.py", line 74, in create_connection
    sock.connect(sa)
ConnectionRefusedError: [Errno 111] Connection refused

During handling of the above exception, another exception occurred:

Traceback (most recent call last):
  File "/usr/local/lib/python3.6/dist-packages/urllib3/connectionpool.py", line 677, in urlopen
    chunked=chunked,
  File "/usr/local/lib/python3.6/dist-packages/urllib3/connectionpool.py", line 392, in _make_request
    conn.request(method, url, **httplib_request_kw)
  File "/usr/lib/python3.6/http/client.py", line 1264, in request
    self._send_request(method, url, body, headers, encode_chunked)
  File "/usr/lib/python3.6/http/client.py", line 1310, in _send_request
    self.endheaders(body, encode_chunked=encode_chunked)
  File "/usr/lib/python3.6/http/client.py", line 1259, in endheaders
    self._send_output(message_body, encode_chunked=encode_chunked)
  File "/usr/lib/python3.6/http/client.py", line 1038, in _send_output
    self.send(msg)
  File "/usr/lib/python3.6/http/client.py", line 976, in send
    self.connect()
  File "/usr/local/lib/python3.6/dist-packages/urllib3/connection.py", line 187, in connect
    conn = self._new_conn()
  File "/usr/local/lib/python3.6/dist-packages/urllib3/connection.py", line 172, in _new_conn
    self, "Failed to establish a new connection: %s" % e
urllib3.exceptions.NewConnectionError: <urllib3.connection.HTTPConnection object at 0x7f6a0d23ba20>: Failed to establish a new connection: [Errno 111] Connection refused

During handling of the above exception, another exception occurred:

Traceback (most recent call last):
  File "/usr/local/lib/python3.6/dist-packages/requests/adapters.py", line 449, in send
    timeout=timeout
  File "/usr/local/lib/python3.6/dist-packages/urllib3/connectionpool.py", line 725, in urlopen
    method, url, error=e, _pool=self, _stacktrace=sys.exc_info()[2]
  File "/usr/local/lib/python3.6/dist-packages/urllib3/util/retry.py", line 439, in increment
    raise MaxRetryError(_pool, url, error or ResponseError(cause))
urllib3.exceptions.MaxRetryError: HTTPConnectionPool(host='172.17.0.1', port=8080): Max retries exceeded with url: /judge_server/heartbeat (Caused by NewConnectionError('<urllib3.connection.HTTPConnection object at 0x7f6a0d23ba20>: Failed to establish a new connection: [Errno 111] Connection refused',))

During handling of the above exception, another exception occurred:

Traceback (most recent call last):
  File "/code/service.py", line 19, in _request
    "Content-Type": "application/json"}, timeout=5).text
  File "/usr/local/lib/python3.6/dist-packages/requests/api.py", line 119, in post
    return request('post', url, data=data, json=json, **kwargs)
  File "/usr/local/lib/python3.6/dist-packages/requests/api.py", line 61, in request
    return session.request(method=method, url=url, **kwargs)
  File "/usr/local/lib/python3.6/dist-packages/requests/sessions.py", line 530, in request
    resp = self.send(prep, **send_kwargs)
  File "/usr/local/lib/python3.6/dist-packages/requests/sessions.py", line 643, in send
    r = adapter.send(request, **kwargs)
  File "/usr/local/lib/python3.6/dist-packages/requests/adapters.py", line 516, in send
    raise ConnectionError(e, request=request)
requests.exceptions.ConnectionError: HTTPConnectionPool(host='172.17.0.1', port=8080): Max retries exceeded with url: /judge_server/heartbeat (Caused by NewConnectionError('<urllib3.connection.HTTPConnection object at 0x7f6a0d23ba20>: Failed to establish a new connection: [Errno 111] Connection refused',))

During handling of the above exception, another exception occurred:

Traceback (most recent call last):
  File "/code/service.py", line 42, in <module>
    service.heartbeat()
  File "/code/service.py", line 35, in heartbeat
    self._request(data)
  File "/code/service.py", line 22, in _request
    raise JudgeServiceError("Heartbeat request failed")
exception.JudgeServiceError
2020-11-07 08:00:27,736 ERROR HTTPConnectionPool(host='172.17.0.1', port=8080): Max retries exceeded with url: /judge_server/heartbeat (Caused by NewConnectionError('<urllib3.connection.HTTPConnection object at 0x7f34ea6d8a90>: Failed to establish a new connection: [Errno 111] Connection refused',))
Traceback (most recent call last):
  File "/usr/local/lib/python3.6/dist-packages/urllib3/connection.py", line 160, in _new_conn
    (self._dns_host, self.port), self.timeout, **extra_kw
  File "/usr/local/lib/python3.6/dist-packages/urllib3/util/connection.py", line 84, in create_connection
    raise err
  File "/usr/local/lib/python3.6/dist-packages/urllib3/util/connection.py", line 74, in create_connection
    sock.connect(sa)
ConnectionRefusedError: [Errno 111] Connection refused

During handling of the above exception, another exception occurred:

Traceback (most recent call last):
  File "/usr/local/lib/python3.6/dist-packages/urllib3/connectionpool.py", line 677, in urlopen
    chunked=chunked,
  File "/usr/local/lib/python3.6/dist-packages/urllib3/connectionpool.py", line 392, in _make_request
    conn.request(method, url, **httplib_request_kw)
  File "/usr/lib/python3.6/http/client.py", line 1264, in request
    self._send_request(method, url, body, headers, encode_chunked)
  File "/usr/lib/python3.6/http/client.py", line 1310, in _send_request
    self.endheaders(body, encode_chunked=encode_chunked)
  File "/usr/lib/python3.6/http/client.py", line 1259, in endheaders
    self._send_output(message_body, encode_chunked=encode_chunked)
  File "/usr/lib/python3.6/http/client.py", line 1038, in _send_output
    self.send(msg)
  File "/usr/lib/python3.6/http/client.py", line 976, in send
    self.connect()
  File "/usr/local/lib/python3.6/dist-packages/urllib3/connection.py", line 187, in connect
    conn = self._new_conn()
  File "/usr/local/lib/python3.6/dist-packages/urllib3/connection.py", line 172, in _new_conn
    self, "Failed to establish a new connection: %s" % e
urllib3.exceptions.NewConnectionError: <urllib3.connection.HTTPConnection object at 0x7f34ea6d8a90>: Failed to establish a new connection: [Errno 111] Connection refused

During handling of the above exception, another exception occurred:

Traceback (most recent call last):
  File "/usr/local/lib/python3.6/dist-packages/requests/adapters.py", line 449, in send
    timeout=timeout
  File "/usr/local/lib/python3.6/dist-packages/urllib3/connectionpool.py", line 725, in urlopen
    method, url, error=e, _pool=self, _stacktrace=sys.exc_info()[2]
  File "/usr/local/lib/python3.6/dist-packages/urllib3/util/retry.py", line 439, in increment
    raise MaxRetryError(_pool, url, error or ResponseError(cause))
urllib3.exceptions.MaxRetryError: HTTPConnectionPool(host='172.17.0.1', port=8080): Max retries exceeded with url: /judge_server/heartbeat (Caused by NewConnectionError('<urllib3.connection.HTTPConnection object at 0x7f34ea6d8a90>: Failed to establish a new connection: [Errno 111] Connection refused',))

During handling of the above exception, another exception occurred:

Traceback (most recent call last):
  File "/code/service.py", line 19, in _request
    "Content-Type": "application/json"}, timeout=5).text
  File "/usr/local/lib/python3.6/dist-packages/requests/api.py", line 119, in post
    return request('post', url, data=data, json=json, **kwargs)
  File "/usr/local/lib/python3.6/dist-packages/requests/api.py", line 61, in request
    return session.request(method=method, url=url, **kwargs)
  File "/usr/local/lib/python3.6/dist-packages/requests/sessions.py", line 530, in request
    resp = self.send(prep, **send_kwargs)
  File "/usr/local/lib/python3.6/dist-packages/requests/sessions.py", line 643, in send
    r = adapter.send(request, **kwargs)
  File "/usr/local/lib/python3.6/dist-packages/requests/adapters.py", line 516, in send
    raise ConnectionError(e, request=request)
requests.exceptions.ConnectionError: HTTPConnectionPool(host='172.17.0.1', port=8080): Max retries exceeded with url: /judge_server/heartbeat (Caused by NewConnectionError('<urllib3.connection.HTTPConnection object at 0x7f34ea6d8a90>: Failed to establish a new connection: [Errno 111] Connection refused',))
2020-11-07 08:00:27,738 ERROR 
Traceback (most recent call last):
  File "/usr/local/lib/python3.6/dist-packages/urllib3/connection.py", line 160, in _new_conn
    (self._dns_host, self.port), self.timeout, **extra_kw
  File "/usr/local/lib/python3.6/dist-packages/urllib3/util/connection.py", line 84, in create_connection
    raise err
  File "/usr/local/lib/python3.6/dist-packages/urllib3/util/connection.py", line 74, in create_connection
    sock.connect(sa)
ConnectionRefusedError: [Errno 111] Connection refused

During handling of the above exception, another exception occurred:

Traceback (most recent call last):
  File "/usr/local/lib/python3.6/dist-packages/urllib3/connectionpool.py", line 677, in urlopen
    chunked=chunked,
  File "/usr/local/lib/python3.6/dist-packages/urllib3/connectionpool.py", line 392, in _make_request
    conn.request(method, url, **httplib_request_kw)
  File "/usr/lib/python3.6/http/client.py", line 1264, in request
    self._send_request(method, url, body, headers, encode_chunked)
  File "/usr/lib/python3.6/http/client.py", line 1310, in _send_request
    self.endheaders(body, encode_chunked=encode_chunked)
  File "/usr/lib/python3.6/http/client.py", line 1259, in endheaders
    self._send_output(message_body, encode_chunked=encode_chunked)
  File "/usr/lib/python3.6/http/client.py", line 1038, in _send_output
    self.send(msg)
  File "/usr/lib/python3.6/http/client.py", line 976, in send
    self.connect()
  File "/usr/local/lib/python3.6/dist-packages/urllib3/connection.py", line 187, in connect
    conn = self._new_conn()
  File "/usr/local/lib/python3.6/dist-packages/urllib3/connection.py", line 172, in _new_conn
    self, "Failed to establish a new connection: %s" % e
urllib3.exceptions.NewConnectionError: <urllib3.connection.HTTPConnection object at 0x7f34ea6d8a90>: Failed to establish a new connection: [Errno 111] Connection refused

During handling of the above exception, another exception occurred:

Traceback (most recent call last):
  File "/usr/local/lib/python3.6/dist-packages/requests/adapters.py", line 449, in send
    timeout=timeout
  File "/usr/local/lib/python3.6/dist-packages/urllib3/connectionpool.py", line 725, in urlopen
    method, url, error=e, _pool=self, _stacktrace=sys.exc_info()[2]
  File "/usr/local/lib/python3.6/dist-packages/urllib3/util/retry.py", line 439, in increment
    raise MaxRetryError(_pool, url, error or ResponseError(cause))
urllib3.exceptions.MaxRetryError: HTTPConnectionPool(host='172.17.0.1', port=8080): Max retries exceeded with url: /judge_server/heartbeat (Caused by NewConnectionError('<urllib3.connection.HTTPConnection object at 0x7f34ea6d8a90>: Failed to establish a new connection: [Errno 111] Connection refused',))

During handling of the above exception, another exception occurred:

Traceback (most recent call last):
  File "/code/service.py", line 19, in _request
    "Content-Type": "application/json"}, timeout=5).text
  File "/usr/local/lib/python3.6/dist-packages/requests/api.py", line 119, in post
    return request('post', url, data=data, json=json, **kwargs)
  File "/usr/local/lib/python3.6/dist-packages/requests/api.py", line 61, in request
    return session.request(method=method, url=url, **kwargs)
  File "/usr/local/lib/python3.6/dist-packages/requests/sessions.py", line 530, in request
    resp = self.send(prep, **send_kwargs)
  File "/usr/local/lib/python3.6/dist-packages/requests/sessions.py", line 643, in send
    r = adapter.send(request, **kwargs)
  File "/usr/local/lib/python3.6/dist-packages/requests/adapters.py", line 516, in send
    raise ConnectionError(e, request=request)
requests.exceptions.ConnectionError: HTTPConnectionPool(host='172.17.0.1', port=8080): Max retries exceeded with url: /judge_server/heartbeat (Caused by NewConnectionError('<urllib3.connection.HTTPConnection object at 0x7f34ea6d8a90>: Failed to establish a new connection: [Errno 111] Connection refused',))

During handling of the above exception, another exception occurred:

Traceback (most recent call last):
  File "/code/service.py", line 42, in <module>
    service.heartbeat()
  File "/code/service.py", line 35, in heartbeat
    self._request(data)
  File "/code/service.py", line 22, in _request
    raise JudgeServiceError("Heartbeat request failed")
exception.JudgeServiceError
2020-11-07 08:00:32,898 ERROR HTTPConnectionPool(host='172.17.0.1', port=8080): Max retries exceeded with url: /judge_server/heartbeat (Caused by NewConnectionError('<urllib3.connection.HTTPConnection object at 0x7f9c1eb9aa90>: Failed to establish a new connection: [Errno 111] Connection refused',))
Traceback (most recent call last):
  File "/usr/local/lib/python3.6/dist-packages/urllib3/connection.py", line 160, in _new_conn
    (self._dns_host, self.port), self.timeout, **extra_kw
  File "/usr/local/lib/python3.6/dist-packages/urllib3/util/connection.py", line 84, in create_connection
    raise err
  File "/usr/local/lib/python3.6/dist-packages/urllib3/util/connection.py", line 74, in create_connection
    sock.connect(sa)
ConnectionRefusedError: [Errno 111] Connection refused

During handling of the above exception, another exception occurred:

Traceback (most recent call last):
  File "/usr/local/lib/python3.6/dist-packages/urllib3/connectionpool.py", line 677, in urlopen
    chunked=chunked,
  File "/usr/local/lib/python3.6/dist-packages/urllib3/connectionpool.py", line 392, in _make_request
    conn.request(method, url, **httplib_request_kw)
  File "/usr/lib/python3.6/http/client.py", line 1264, in request
    self._send_request(method, url, body, headers, encode_chunked)
  File "/usr/lib/python3.6/http/client.py", line 1310, in _send_request
    self.endheaders(body, encode_chunked=encode_chunked)
  File "/usr/lib/python3.6/http/client.py", line 1259, in endheaders
    self._send_output(message_body, encode_chunked=encode_chunked)
  File "/usr/lib/python3.6/http/client.py", line 1038, in _send_output
    self.send(msg)
  File "/usr/lib/python3.6/http/client.py", line 976, in send
    self.connect()
  File "/usr/local/lib/python3.6/dist-packages/urllib3/connection.py", line 187, in connect
    conn = self._new_conn()
  File "/usr/local/lib/python3.6/dist-packages/urllib3/connection.py", line 172, in _new_conn
    self, "Failed to establish a new connection: %s" % e
urllib3.exceptions.NewConnectionError: <urllib3.connection.HTTPConnection object at 0x7f9c1eb9aa90>: Failed to establish a new connection: [Errno 111] Connection refused

During handling of the above exception, another exception occurred:

Traceback (most recent call last):
  File "/usr/local/lib/python3.6/dist-packages/requests/adapters.py", line 449, in send
    timeout=timeout
  File "/usr/local/lib/python3.6/dist-packages/urllib3/connectionpool.py", line 725, in urlopen
    method, url, error=e, _pool=self, _stacktrace=sys.exc_info()[2]
  File "/usr/local/lib/python3.6/dist-packages/urllib3/util/retry.py", line 439, in increment
    raise MaxRetryError(_pool, url, error or ResponseError(cause))
urllib3.exceptions.MaxRetryError: HTTPConnectionPool(host='172.17.0.1', port=8080): Max retries exceeded with url: /judge_server/heartbeat (Caused by NewConnectionError('<urllib3.connection.HTTPConnection object at 0x7f9c1eb9aa90>: Failed to establish a new connection: [Errno 111] Connection refused',))

During handling of the above exception, another exception occurred:

Traceback (most recent call last):
  File "/code/service.py", line 19, in _request
    "Content-Type": "application/json"}, timeout=5).text
  File "/usr/local/lib/python3.6/dist-packages/requests/api.py", line 119, in post
    return request('post', url, data=data, json=json, **kwargs)
  File "/usr/local/lib/python3.6/dist-packages/requests/api.py", line 61, in request
    return session.request(method=method, url=url, **kwargs)
  File "/usr/local/lib/python3.6/dist-packages/requests/sessions.py", line 530, in request
    resp = self.send(prep, **send_kwargs)
  File "/usr/local/lib/python3.6/dist-packages/requests/sessions.py", line 643, in send
    r = adapter.send(request, **kwargs)
  File "/usr/local/lib/python3.6/dist-packages/requests/adapters.py", line 516, in send
    raise ConnectionError(e, request=request)
requests.exceptions.ConnectionError: HTTPConnectionPool(host='172.17.0.1', port=8080): Max retries exceeded with url: /judge_server/heartbeat (Caused by NewConnectionError('<urllib3.connection.HTTPConnection object at 0x7f9c1eb9aa90>: Failed to establish a new connection: [Errno 111] Connection refused',))
2020-11-07 08:00:32,899 ERROR 
Traceback (most recent call last):
  File "/usr/local/lib/python3.6/dist-packages/urllib3/connection.py", line 160, in _new_conn
    (self._dns_host, self.port), self.timeout, **extra_kw
  File "/usr/local/lib/python3.6/dist-packages/urllib3/util/connection.py", line 84, in create_connection
    raise err
  File "/usr/local/lib/python3.6/dist-packages/urllib3/util/connection.py", line 74, in create_connection
    sock.connect(sa)
ConnectionRefusedError: [Errno 111] Connection refused

During handling of the above exception, another exception occurred:

Traceback (most recent call last):
  File "/usr/local/lib/python3.6/dist-packages/urllib3/connectionpool.py", line 677, in urlopen
    chunked=chunked,
  File "/usr/local/lib/python3.6/dist-packages/urllib3/connectionpool.py", line 392, in _make_request
    conn.request(method, url, **httplib_request_kw)
  File "/usr/lib/python3.6/http/client.py", line 1264, in request
    self._send_request(method, url, body, headers, encode_chunked)
  File "/usr/lib/python3.6/http/client.py", line 1310, in _send_request
    self.endheaders(body, encode_chunked=encode_chunked)
  File "/usr/lib/python3.6/http/client.py", line 1259, in endheaders
    self._send_output(message_body, encode_chunked=encode_chunked)
  File "/usr/lib/python3.6/http/client.py", line 1038, in _send_output
    self.send(msg)
  File "/usr/lib/python3.6/http/client.py", line 976, in send
    self.connect()
  File "/usr/local/lib/python3.6/dist-packages/urllib3/connection.py", line 187, in connect
    conn = self._new_conn()
  File "/usr/local/lib/python3.6/dist-packages/urllib3/connection.py", line 172, in _new_conn
    self, "Failed to establish a new connection: %s" % e
urllib3.exceptions.NewConnectionError: <urllib3.connection.HTTPConnection object at 0x7f9c1eb9aa90>: Failed to establish a new connection: [Errno 111] Connection refused

During handling of the above exception, another exception occurred:

Traceback (most recent call last):
  File "/usr/local/lib/python3.6/dist-packages/requests/adapters.py", line 449, in send
    timeout=timeout
  File "/usr/local/lib/python3.6/dist-packages/urllib3/connectionpool.py", line 725, in urlopen
    method, url, error=e, _pool=self, _stacktrace=sys.exc_info()[2]
  File "/usr/local/lib/python3.6/dist-packages/urllib3/util/retry.py", line 439, in increment
    raise MaxRetryError(_pool, url, error or ResponseError(cause))
urllib3.exceptions.MaxRetryError: HTTPConnectionPool(host='172.17.0.1', port=8080): Max retries exceeded with url: /judge_server/heartbeat (Caused by NewConnectionError('<urllib3.connection.HTTPConnection object at 0x7f9c1eb9aa90>: Failed to establish a new connection: [Errno 111] Connection refused',))

During handling of the above exception, another exception occurred:

Traceback (most recent call last):
  File "/code/service.py", line 19, in _request
    "Content-Type": "application/json"}, timeout=5).text
  File "/usr/local/lib/python3.6/dist-packages/requests/api.py", line 119, in post
    return request('post', url, data=data, json=json, **kwargs)
  File "/usr/local/lib/python3.6/dist-packages/requests/api.py", line 61, in request
    return session.request(method=method, url=url, **kwargs)
  File "/usr/local/lib/python3.6/dist-packages/requests/sessions.py", line 530, in request
    resp = self.send(prep, **send_kwargs)
  File "/usr/local/lib/python3.6/dist-packages/requests/sessions.py", line 643, in send
    r = adapter.send(request, **kwargs)
  File "/usr/local/lib/python3.6/dist-packages/requests/adapters.py", line 516, in send
    raise ConnectionError(e, request=request)
requests.exceptions.ConnectionError: HTTPConnectionPool(host='172.17.0.1', port=8080): Max retries exceeded with url: /judge_server/heartbeat (Caused by NewConnectionError('<urllib3.connection.HTTPConnection object at 0x7f9c1eb9aa90>: Failed to establish a new connection: [Errno 111] Connection refused',))

During handling of the above exception, another exception occurred:

Traceback (most recent call last):
  File "/code/service.py", line 42, in <module>
    service.heartbeat()
  File "/code/service.py", line 35, in heartbeat
    self._request(data)
  File "/code/service.py", line 22, in _request
    raise JudgeServiceError("Heartbeat request failed")
exception.JudgeServiceError
2020-11-07 08:00:38,065 ERROR HTTPConnectionPool(host='172.17.0.1', port=8080): Max retries exceeded with url: /judge_server/heartbeat (Caused by NewConnectionError('<urllib3.connection.HTTPConnection object at 0x7f7f2c49aa90>: Failed to establish a new connection: [Errno 111] Connection refused',))
Traceback (most recent call last):
  File "/usr/local/lib/python3.6/dist-packages/urllib3/connection.py", line 160, in _new_conn
    (self._dns_host, self.port), self.timeout, **extra_kw
  File "/usr/local/lib/python3.6/dist-packages/urllib3/util/connection.py", line 84, in create_connection
    raise err
  File "/usr/local/lib/python3.6/dist-packages/urllib3/util/connection.py", line 74, in create_connection
    sock.connect(sa)
ConnectionRefusedError: [Errno 111] Connection refused

During handling of the above exception, another exception occurred:

Traceback (most recent call last):
  File "/usr/local/lib/python3.6/dist-packages/urllib3/connectionpool.py", line 677, in urlopen
    chunked=chunked,
  File "/usr/local/lib/python3.6/dist-packages/urllib3/connectionpool.py", line 392, in _make_request
    conn.request(method, url, **httplib_request_kw)
  File "/usr/lib/python3.6/http/client.py", line 1264, in request
    self._send_request(method, url, body, headers, encode_chunked)
  File "/usr/lib/python3.6/http/client.py", line 1310, in _send_request
    self.endheaders(body, encode_chunked=encode_chunked)
  File "/usr/lib/python3.6/http/client.py", line 1259, in endheaders
    self._send_output(message_body, encode_chunked=encode_chunked)
  File "/usr/lib/python3.6/http/client.py", line 1038, in _send_output
    self.send(msg)
  File "/usr/lib/python3.6/http/client.py", line 976, in send
    self.connect()
  File "/usr/local/lib/python3.6/dist-packages/urllib3/connection.py", line 187, in connect
    conn = self._new_conn()
  File "/usr/local/lib/python3.6/dist-packages/urllib3/connection.py", line 172, in _new_conn
    self, "Failed to establish a new connection: %s" % e
urllib3.exceptions.NewConnectionError: <urllib3.connection.HTTPConnection object at 0x7f7f2c49aa90>: Failed to establish a new connection: [Errno 111] Connection refused

During handling of the above exception, another exception occurred:

Traceback (most recent call last):
  File "/usr/local/lib/python3.6/dist-packages/requests/adapters.py", line 449, in send
    timeout=timeout
  File "/usr/local/lib/python3.6/dist-packages/urllib3/connectionpool.py", line 725, in urlopen
    method, url, error=e, _pool=self, _stacktrace=sys.exc_info()[2]
  File "/usr/local/lib/python3.6/dist-packages/urllib3/util/retry.py", line 439, in increment
    raise MaxRetryError(_pool, url, error or ResponseError(cause))
urllib3.exceptions.MaxRetryError: HTTPConnectionPool(host='172.17.0.1', port=8080): Max retries exceeded with url: /judge_server/heartbeat (Caused by NewConnectionError('<urllib3.connection.HTTPConnection object at 0x7f7f2c49aa90>: Failed to establish a new connection: [Errno 111] Connection refused',))

During handling of the above exception, another exception occurred:

Traceback (most recent call last):
  File "/code/service.py", line 19, in _request
    "Content-Type": "application/json"}, timeout=5).text
  File "/usr/local/lib/python3.6/dist-packages/requests/api.py", line 119, in post
    return request('post', url, data=data, json=json, **kwargs)
  File "/usr/local/lib/python3.6/dist-packages/requests/api.py", line 61, in request
    return session.request(method=method, url=url, **kwargs)
  File "/usr/local/lib/python3.6/dist-packages/requests/sessions.py", line 530, in request
    resp = self.send(prep, **send_kwargs)
  File "/usr/local/lib/python3.6/dist-packages/requests/sessions.py", line 643, in send
    r = adapter.send(request, **kwargs)
  File "/usr/local/lib/python3.6/dist-packages/requests/adapters.py", line 516, in send
    raise ConnectionError(e, request=request)
requests.exceptions.ConnectionError: HTTPConnectionPool(host='172.17.0.1', port=8080): Max retries exceeded with url: /judge_server/heartbeat (Caused by NewConnectionError('<urllib3.connection.HTTPConnection object at 0x7f7f2c49aa90>: Failed to establish a new connection: [Errno 111] Connection refused',))
2020-11-07 08:00:38,066 ERROR 
Traceback (most recent call last):
  File "/usr/local/lib/python3.6/dist-packages/urllib3/connection.py", line 160, in _new_conn
    (self._dns_host, self.port), self.timeout, **extra_kw
  File "/usr/local/lib/python3.6/dist-packages/urllib3/util/connection.py", line 84, in create_connection
    raise err
  File "/usr/local/lib/python3.6/dist-packages/urllib3/util/connection.py", line 74, in create_connection
    sock.connect(sa)
ConnectionRefusedError: [Errno 111] Connection refused

During handling of the above exception, another exception occurred:

Traceback (most recent call last):
  File "/usr/local/lib/python3.6/dist-packages/urllib3/connectionpool.py", line 677, in urlopen
    chunked=chunked,
  File "/usr/local/lib/python3.6/dist-packages/urllib3/connectionpool.py", line 392, in _make_request
    conn.request(method, url, **httplib_request_kw)
  File "/usr/lib/python3.6/http/client.py", line 1264, in request
    self._send_request(method, url, body, headers, encode_chunked)
  File "/usr/lib/python3.6/http/client.py", line 1310, in _send_request
    self.endheaders(body, encode_chunked=encode_chunked)
  File "/usr/lib/python3.6/http/client.py", line 1259, in endheaders
    self._send_output(message_body, encode_chunked=encode_chunked)
  File "/usr/lib/python3.6/http/client.py", line 1038, in _send_output
    self.send(msg)
  File "/usr/lib/python3.6/http/client.py", line 976, in send
    self.connect()
  File "/usr/local/lib/python3.6/dist-packages/urllib3/connection.py", line 187, in connect
    conn = self._new_conn()
  File "/usr/local/lib/python3.6/dist-packages/urllib3/connection.py", line 172, in _new_conn
    self, "Failed to establish a new connection: %s" % e
urllib3.exceptions.NewConnectionError: <urllib3.connection.HTTPConnection object at 0x7f7f2c49aa90>: Failed to establish a new connection: [Errno 111] Connection refused

During handling of the above exception, another exception occurred:

Traceback (most recent call last):
  File "/usr/local/lib/python3.6/dist-packages/requests/adapters.py", line 449, in send
    timeout=timeout
  File "/usr/local/lib/python3.6/dist-packages/urllib3/connectionpool.py", line 725, in urlopen
    method, url, error=e, _pool=self, _stacktrace=sys.exc_info()[2]
  File "/usr/local/lib/python3.6/dist-packages/urllib3/util/retry.py", line 439, in increment
    raise MaxRetryError(_pool, url, error or ResponseError(cause))
urllib3.exceptions.MaxRetryError: HTTPConnectionPool(host='172.17.0.1', port=8080): Max retries exceeded with url: /judge_server/heartbeat (Caused by NewConnectionError('<urllib3.connection.HTTPConnection object at 0x7f7f2c49aa90>: Failed to establish a new connection: [Errno 111] Connection refused',))

During handling of the above exception, another exception occurred:

Traceback (most recent call last):
  File "/code/service.py", line 19, in _request
    "Content-Type": "application/json"}, timeout=5).text
  File "/usr/local/lib/python3.6/dist-packages/requests/api.py", line 119, in post
    return request('post', url, data=data, json=json, **kwargs)
  File "/usr/local/lib/python3.6/dist-packages/requests/api.py", line 61, in request
    return session.request(method=method, url=url, **kwargs)
  File "/usr/local/lib/python3.6/dist-packages/requests/sessions.py", line 530, in request
    resp = self.send(prep, **send_kwargs)
  File "/usr/local/lib/python3.6/dist-packages/requests/sessions.py", line 643, in send
    r = adapter.send(request, **kwargs)
  File "/usr/local/lib/python3.6/dist-packages/requests/adapters.py", line 516, in send
    raise ConnectionError(e, request=request)
requests.exceptions.ConnectionError: HTTPConnectionPool(host='172.17.0.1', port=8080): Max retries exceeded with url: /judge_server/heartbeat (Caused by NewConnectionError('<urllib3.connection.HTTPConnection object at 0x7f7f2c49aa90>: Failed to establish a new connection: [Errno 111] Connection refused',))

During handling of the above exception, another exception occurred:

Traceback (most recent call last):
  File "/code/service.py", line 42, in <module>
    service.heartbeat()
  File "/code/service.py", line 35, in heartbeat
    self._request(data)
  File "/code/service.py", line 22, in _request
    raise JudgeServiceError("Heartbeat request failed")
exception.JudgeServiceError
2020-11-07 08:00:43,275 ERROR HTTPConnectionPool(host='172.17.0.1', port=8080): Max retries exceeded with url: /judge_server/heartbeat (Caused by NewConnectionError('<urllib3.connection.HTTPConnection object at 0x7f042962cac8>: Failed to establish a new connection: [Errno 111] Connection refused',))
Traceback (most recent call last):
  File "/usr/local/lib/python3.6/dist-packages/urllib3/connection.py", line 160, in _new_conn
    (self._dns_host, self.port), self.timeout, **extra_kw
  File "/usr/local/lib/python3.6/dist-packages/urllib3/util/connection.py", line 84, in create_connection
    raise err
  File "/usr/local/lib/python3.6/dist-packages/urllib3/util/connection.py", line 74, in create_connection
    sock.connect(sa)
ConnectionRefusedError: [Errno 111] Connection refused

During handling of the above exception, another exception occurred:

Traceback (most recent call last):
  File "/usr/local/lib/python3.6/dist-packages/urllib3/connectionpool.py", line 677, in urlopen
    chunked=chunked,
  File "/usr/local/lib/python3.6/dist-packages/urllib3/connectionpool.py", line 392, in _make_request
    conn.request(method, url, **httplib_request_kw)
  File "/usr/lib/python3.6/http/client.py", line 1264, in request
    self._send_request(method, url, body, headers, encode_chunked)
  File "/usr/lib/python3.6/http/client.py", line 1310, in _send_request
    self.endheaders(body, encode_chunked=encode_chunked)
  File "/usr/lib/python3.6/http/client.py", line 1259, in endheaders
    self._send_output(message_body, encode_chunked=encode_chunked)
  File "/usr/lib/python3.6/http/client.py", line 1038, in _send_output
    self.send(msg)
  File "/usr/lib/python3.6/http/client.py", line 976, in send
    self.connect()
  File "/usr/local/lib/python3.6/dist-packages/urllib3/connection.py", line 187, in connect
    conn = self._new_conn()
  File "/usr/local/lib/python3.6/dist-packages/urllib3/connection.py", line 172, in _new_conn
    self, "Failed to establish a new connection: %s" % e
urllib3.exceptions.NewConnectionError: <urllib3.connection.HTTPConnection object at 0x7f042962cac8>: Failed to establish a new connection: [Errno 111] Connection refused

During handling of the above exception, another exception occurred:

Traceback (most recent call last):
  File "/usr/local/lib/python3.6/dist-packages/requests/adapters.py", line 449, in send
    timeout=timeout
  File "/usr/local/lib/python3.6/dist-packages/urllib3/connectionpool.py", line 725, in urlopen
    method, url, error=e, _pool=self, _stacktrace=sys.exc_info()[2]
  File "/usr/local/lib/python3.6/dist-packages/urllib3/util/retry.py", line 439, in increment
    raise MaxRetryError(_pool, url, error or ResponseError(cause))
urllib3.exceptions.MaxRetryError: HTTPConnectionPool(host='172.17.0.1', port=8080): Max retries exceeded with url: /judge_server/heartbeat (Caused by NewConnectionError('<urllib3.connection.HTTPConnection object at 0x7f042962cac8>: Failed to establish a new connection: [Errno 111] Connection refused',))

During handling of the above exception, another exception occurred:

Traceback (most recent call last):
  File "/code/service.py", line 19, in _request
    "Content-Type": "application/json"}, timeout=5).text
  File "/usr/local/lib/python3.6/dist-packages/requests/api.py", line 119, in post
    return request('post', url, data=data, json=json, **kwargs)
  File "/usr/local/lib/python3.6/dist-packages/requests/api.py", line 61, in request
    return session.request(method=method, url=url, **kwargs)
  File "/usr/local/lib/python3.6/dist-packages/requests/sessions.py", line 530, in request
    resp = self.send(prep, **send_kwargs)
  File "/usr/local/lib/python3.6/dist-packages/requests/sessions.py", line 643, in send
    r = adapter.send(request, **kwargs)
  File "/usr/local/lib/python3.6/dist-packages/requests/adapters.py", line 516, in send
    raise ConnectionError(e, request=request)
requests.exceptions.ConnectionError: HTTPConnectionPool(host='172.17.0.1', port=8080): Max retries exceeded with url: /judge_server/heartbeat (Caused by NewConnectionError('<urllib3.connection.HTTPConnection object at 0x7f042962cac8>: Failed to establish a new connection: [Errno 111] Connection refused',))
2020-11-07 08:00:43,276 ERROR 
Traceback (most recent call last):
  File "/usr/local/lib/python3.6/dist-packages/urllib3/connection.py", line 160, in _new_conn
    (self._dns_host, self.port), self.timeout, **extra_kw
  File "/usr/local/lib/python3.6/dist-packages/urllib3/util/connection.py", line 84, in create_connection
    raise err
  File "/usr/local/lib/python3.6/dist-packages/urllib3/util/connection.py", line 74, in create_connection
    sock.connect(sa)
ConnectionRefusedError: [Errno 111] Connection refused

During handling of the above exception, another exception occurred:

Traceback (most recent call last):
  File "/usr/local/lib/python3.6/dist-packages/urllib3/connectionpool.py", line 677, in urlopen
    chunked=chunked,
  File "/usr/local/lib/python3.6/dist-packages/urllib3/connectionpool.py", line 392, in _make_request
    conn.request(method, url, **httplib_request_kw)
  File "/usr/lib/python3.6/http/client.py", line 1264, in request
    self._send_request(method, url, body, headers, encode_chunked)
  File "/usr/lib/python3.6/http/client.py", line 1310, in _send_request
    self.endheaders(body, encode_chunked=encode_chunked)
  File "/usr/lib/python3.6/http/client.py", line 1259, in endheaders
    self._send_output(message_body, encode_chunked=encode_chunked)
  File "/usr/lib/python3.6/http/client.py", line 1038, in _send_output
    self.send(msg)
  File "/usr/lib/python3.6/http/client.py", line 976, in send
    self.connect()
  File "/usr/local/lib/python3.6/dist-packages/urllib3/connection.py", line 187, in connect
    conn = self._new_conn()
  File "/usr/local/lib/python3.6/dist-packages/urllib3/connection.py", line 172, in _new_conn
    self, "Failed to establish a new connection: %s" % e
urllib3.exceptions.NewConnectionError: <urllib3.connection.HTTPConnection object at 0x7f042962cac8>: Failed to establish a new connection: [Errno 111] Connection refused

During handling of the above exception, another exception occurred:

Traceback (most recent call last):
  File "/usr/local/lib/python3.6/dist-packages/requests/adapters.py", line 449, in send
    timeout=timeout
  File "/usr/local/lib/python3.6/dist-packages/urllib3/connectionpool.py", line 725, in urlopen
    method, url, error=e, _pool=self, _stacktrace=sys.exc_info()[2]
  File "/usr/local/lib/python3.6/dist-packages/urllib3/util/retry.py", line 439, in increment
    raise MaxRetryError(_pool, url, error or ResponseError(cause))
urllib3.exceptions.MaxRetryError: HTTPConnectionPool(host='172.17.0.1', port=8080): Max retries exceeded with url: /judge_server/heartbeat (Caused by NewConnectionError('<urllib3.connection.HTTPConnection object at 0x7f042962cac8>: Failed to establish a new connection: [Errno 111] Connection refused',))

During handling of the above exception, another exception occurred:

Traceback (most recent call last):
  File "/code/service.py", line 19, in _request
    "Content-Type": "application/json"}, timeout=5).text
  File "/usr/local/lib/python3.6/dist-packages/requests/api.py", line 119, in post
    return request('post', url, data=data, json=json, **kwargs)
  File "/usr/local/lib/python3.6/dist-packages/requests/api.py", line 61, in request
    return session.request(method=method, url=url, **kwargs)
  File "/usr/local/lib/python3.6/dist-packages/requests/sessions.py", line 530, in request
    resp = self.send(prep, **send_kwargs)
  File "/usr/local/lib/python3.6/dist-packages/requests/sessions.py", line 643, in send
    r = adapter.send(request, **kwargs)
  File "/usr/local/lib/python3.6/dist-packages/requests/adapters.py", line 516, in send
    raise ConnectionError(e, request=request)
requests.exceptions.ConnectionError: HTTPConnectionPool(host='172.17.0.1', port=8080): Max retries exceeded with url: /judge_server/heartbeat (Caused by NewConnectionError('<urllib3.connection.HTTPConnection object at 0x7f042962cac8>: Failed to establish a new connection: [Errno 111] Connection refused',))

During handling of the above exception, another exception occurred:

Traceback (most recent call last):
  File "/code/service.py", line 42, in <module>
    service.heartbeat()
  File "/code/service.py", line 35, in heartbeat
    self._request(data)
  File "/code/service.py", line 22, in _request
    raise JudgeServiceError("Heartbeat request failed")
exception.JudgeServiceError
2020-11-07 08:01:29,696 ERROR HTTPConnectionPool(host='172.17.0.1', port=8080): Read timed out. (read timeout=5)
Traceback (most recent call last):
  File "/usr/local/lib/python3.6/dist-packages/urllib3/connectionpool.py", line 426, in _make_request
    six.raise_from(e, None)
  File "<string>", line 3, in raise_from
  File "/usr/local/lib/python3.6/dist-packages/urllib3/connectionpool.py", line 421, in _make_request
    httplib_response = conn.getresponse()
  File "/usr/lib/python3.6/http/client.py", line 1356, in getresponse
    response.begin()
  File "/usr/lib/python3.6/http/client.py", line 307, in begin
    version, status, reason = self._read_status()
  File "/usr/lib/python3.6/http/client.py", line 268, in _read_status
    line = str(self.fp.readline(_MAXLINE + 1), "iso-8859-1")
  File "/usr/lib/python3.6/socket.py", line 586, in readinto
    return self._sock.recv_into(b)
socket.timeout: timed out

During handling of the above exception, another exception occurred:

Traceback (most recent call last):
  File "/usr/local/lib/python3.6/dist-packages/requests/adapters.py", line 449, in send
    timeout=timeout
  File "/usr/local/lib/python3.6/dist-packages/urllib3/connectionpool.py", line 725, in urlopen
    method, url, error=e, _pool=self, _stacktrace=sys.exc_info()[2]
  File "/usr/local/lib/python3.6/dist-packages/urllib3/util/retry.py", line 403, in increment
    raise six.reraise(type(error), error, _stacktrace)
  File "/usr/local/lib/python3.6/dist-packages/urllib3/packages/six.py", line 735, in reraise
    raise value
  File "/usr/local/lib/python3.6/dist-packages/urllib3/connectionpool.py", line 677, in urlopen
    chunked=chunked,
  File "/usr/local/lib/python3.6/dist-packages/urllib3/connectionpool.py", line 428, in _make_request
    self._raise_timeout(err=e, url=url, timeout_value=read_timeout)
  File "/usr/local/lib/python3.6/dist-packages/urllib3/connectionpool.py", line 336, in _raise_timeout
    self, url, "Read timed out. (read timeout=%s)" % timeout_value
urllib3.exceptions.ReadTimeoutError: HTTPConnectionPool(host='172.17.0.1', port=8080): Read timed out. (read timeout=5)

During handling of the above exception, another exception occurred:

Traceback (most recent call last):
  File "/code/service.py", line 19, in _request
    "Content-Type": "application/json"}, timeout=5).text
  File "/usr/local/lib/python3.6/dist-packages/requests/api.py", line 119, in post
    return request('post', url, data=data, json=json, **kwargs)
  File "/usr/local/lib/python3.6/dist-packages/requests/api.py", line 61, in request
    return session.request(method=method, url=url, **kwargs)
  File "/usr/local/lib/python3.6/dist-packages/requests/sessions.py", line 530, in request
    resp = self.send(prep, **send_kwargs)
  File "/usr/local/lib/python3.6/dist-packages/requests/sessions.py", line 643, in send
    r = adapter.send(request, **kwargs)
  File "/usr/local/lib/python3.6/dist-packages/requests/adapters.py", line 529, in send
    raise ReadTimeout(e, request=request)
requests.exceptions.ReadTimeout: HTTPConnectionPool(host='172.17.0.1', port=8080): Read timed out. (read timeout=5)
2020-11-07 08:01:29,699 ERROR 
Traceback (most recent call last):
  File "/usr/local/lib/python3.6/dist-packages/urllib3/connectionpool.py", line 426, in _make_request
    six.raise_from(e, None)
  File "<string>", line 3, in raise_from
  File "/usr/local/lib/python3.6/dist-packages/urllib3/connectionpool.py", line 421, in _make_request
    httplib_response = conn.getresponse()
  File "/usr/lib/python3.6/http/client.py", line 1356, in getresponse
    response.begin()
  File "/usr/lib/python3.6/http/client.py", line 307, in begin
    version, status, reason = self._read_status()
  File "/usr/lib/python3.6/http/client.py", line 268, in _read_status
    line = str(self.fp.readline(_MAXLINE + 1), "iso-8859-1")
  File "/usr/lib/python3.6/socket.py", line 586, in readinto
    return self._sock.recv_into(b)
socket.timeout: timed out

During handling of the above exception, another exception occurred:

Traceback (most recent call last):
  File "/usr/local/lib/python3.6/dist-packages/requests/adapters.py", line 449, in send
    timeout=timeout
  File "/usr/local/lib/python3.6/dist-packages/urllib3/connectionpool.py", line 725, in urlopen
    method, url, error=e, _pool=self, _stacktrace=sys.exc_info()[2]
  File "/usr/local/lib/python3.6/dist-packages/urllib3/util/retry.py", line 403, in increment
    raise six.reraise(type(error), error, _stacktrace)
  File "/usr/local/lib/python3.6/dist-packages/urllib3/packages/six.py", line 735, in reraise
    raise value
  File "/usr/local/lib/python3.6/dist-packages/urllib3/connectionpool.py", line 677, in urlopen
    chunked=chunked,
  File "/usr/local/lib/python3.6/dist-packages/urllib3/connectionpool.py", line 428, in _make_request
    self._raise_timeout(err=e, url=url, timeout_value=read_timeout)
  File "/usr/local/lib/python3.6/dist-packages/urllib3/connectionpool.py", line 336, in _raise_timeout
    self, url, "Read timed out. (read timeout=%s)" % timeout_value
urllib3.exceptions.ReadTimeoutError: HTTPConnectionPool(host='172.17.0.1', port=8080): Read timed out. (read timeout=5)

During handling of the above exception, another exception occurred:

Traceback (most recent call last):
  File "/code/service.py", line 19, in _request
    "Content-Type": "application/json"}, timeout=5).text
  File "/usr/local/lib/python3.6/dist-packages/requests/api.py", line 119, in post
    return request('post', url, data=data, json=json, **kwargs)
  File "/usr/local/lib/python3.6/dist-packages/requests/api.py", line 61, in request
    return session.request(method=method, url=url, **kwargs)
  File "/usr/local/lib/python3.6/dist-packages/requests/sessions.py", line 530, in request
    resp = self.send(prep, **send_kwargs)
  File "/usr/local/lib/python3.6/dist-packages/requests/sessions.py", line 643, in send
    r = adapter.send(request, **kwargs)
  File "/usr/local/lib/python3.6/dist-packages/requests/adapters.py", line 529, in send
    raise ReadTimeout(e, request=request)
requests.exceptions.ReadTimeout: HTTPConnectionPool(host='172.17.0.1', port=8080): Read timed out. (read timeout=5)

During handling of the above exception, another exception occurred:

Traceback (most recent call last):
  File "/code/service.py", line 42, in <module>
    service.heartbeat()
  File "/code/service.py", line 35, in heartbeat
    self._request(data)
  File "/code/service.py", line 22, in _request
    raise JudgeServiceError("Heartbeat request failed")
exception.JudgeServiceError
2020-11-07 08:02:16,171 ERROR HTTPConnectionPool(host='172.17.0.1', port=8080): Read timed out. (read timeout=5)
Traceback (most recent call last):
  File "/usr/local/lib/python3.6/dist-packages/urllib3/connectionpool.py", line 426, in _make_request
    six.raise_from(e, None)
  File "<string>", line 3, in raise_from
  File "/usr/local/lib/python3.6/dist-packages/urllib3/connectionpool.py", line 421, in _make_request
    httplib_response = conn.getresponse()
  File "/usr/lib/python3.6/http/client.py", line 1356, in getresponse
    response.begin()
  File "/usr/lib/python3.6/http/client.py", line 307, in begin
    version, status, reason = self._read_status()
  File "/usr/lib/python3.6/http/client.py", line 268, in _read_status
    line = str(self.fp.readline(_MAXLINE + 1), "iso-8859-1")
  File "/usr/lib/python3.6/socket.py", line 586, in readinto
    return self._sock.recv_into(b)
socket.timeout: timed out

During handling of the above exception, another exception occurred:

Traceback (most recent call last):
  File "/usr/local/lib/python3.6/dist-packages/requests/adapters.py", line 449, in send
    timeout=timeout
  File "/usr/local/lib/python3.6/dist-packages/urllib3/connectionpool.py", line 725, in urlopen
    method, url, error=e, _pool=self, _stacktrace=sys.exc_info()[2]
  File "/usr/local/lib/python3.6/dist-packages/urllib3/util/retry.py", line 403, in increment
    raise six.reraise(type(error), error, _stacktrace)
  File "/usr/local/lib/python3.6/dist-packages/urllib3/packages/six.py", line 735, in reraise
    raise value
  File "/usr/local/lib/python3.6/dist-packages/urllib3/connectionpool.py", line 677, in urlopen
    chunked=chunked,
  File "/usr/local/lib/python3.6/dist-packages/urllib3/connectionpool.py", line 428, in _make_request
    self._raise_timeout(err=e, url=url, timeout_value=read_timeout)
  File "/usr/local/lib/python3.6/dist-packages/urllib3/connectionpool.py", line 336, in _raise_timeout
    self, url, "Read timed out. (read timeout=%s)" % timeout_value
urllib3.exceptions.ReadTimeoutError: HTTPConnectionPool(host='172.17.0.1', port=8080): Read timed out. (read timeout=5)

During handling of the above exception, another exception occurred:

Traceback (most recent call last):
  File "/code/service.py", line 19, in _request
    "Content-Type": "application/json"}, timeout=5).text
  File "/usr/local/lib/python3.6/dist-packages/requests/api.py", line 119, in post
    return request('post', url, data=data, json=json, **kwargs)
  File "/usr/local/lib/python3.6/dist-packages/requests/api.py", line 61, in request
    return session.request(method=method, url=url, **kwargs)
  File "/usr/local/lib/python3.6/dist-packages/requests/sessions.py", line 530, in request
    resp = self.send(prep, **send_kwargs)
  File "/usr/local/lib/python3.6/dist-packages/requests/sessions.py", line 643, in send
    r = adapter.send(request, **kwargs)
  File "/usr/local/lib/python3.6/dist-packages/requests/adapters.py", line 529, in send
    raise ReadTimeout(e, request=request)
requests.exceptions.ReadTimeout: HTTPConnectionPool(host='172.17.0.1', port=8080): Read timed out. (read timeout=5)
2020-11-07 08:02:16,173 ERROR 
Traceback (most recent call last):
  File "/usr/local/lib/python3.6/dist-packages/urllib3/connectionpool.py", line 426, in _make_request
    six.raise_from(e, None)
  File "<string>", line 3, in raise_from
  File "/usr/local/lib/python3.6/dist-packages/urllib3/connectionpool.py", line 421, in _make_request
    httplib_response = conn.getresponse()
  File "/usr/lib/python3.6/http/client.py", line 1356, in getresponse
    response.begin()
  File "/usr/lib/python3.6/http/client.py", line 307, in begin
    version, status, reason = self._read_status()
  File "/usr/lib/python3.6/http/client.py", line 268, in _read_status
    line = str(self.fp.readline(_MAXLINE + 1), "iso-8859-1")
  File "/usr/lib/python3.6/socket.py", line 586, in readinto
    return self._sock.recv_into(b)
socket.timeout: timed out

During handling of the above exception, another exception occurred:

Traceback (most recent call last):
  File "/usr/local/lib/python3.6/dist-packages/requests/adapters.py", line 449, in send
    timeout=timeout
  File "/usr/local/lib/python3.6/dist-packages/urllib3/connectionpool.py", line 725, in urlopen
    method, url, error=e, _pool=self, _stacktrace=sys.exc_info()[2]
  File "/usr/local/lib/python3.6/dist-packages/urllib3/util/retry.py", line 403, in increment
    raise six.reraise(type(error), error, _stacktrace)
  File "/usr/local/lib/python3.6/dist-packages/urllib3/packages/six.py", line 735, in reraise
    raise value
  File "/usr/local/lib/python3.6/dist-packages/urllib3/connectionpool.py", line 677, in urlopen
    chunked=chunked,
  File "/usr/local/lib/python3.6/dist-packages/urllib3/connectionpool.py", line 428, in _make_request
    self._raise_timeout(err=e, url=url, timeout_value=read_timeout)
  File "/usr/local/lib/python3.6/dist-packages/urllib3/connectionpool.py", line 336, in _raise_timeout
    self, url, "Read timed out. (read timeout=%s)" % timeout_value
urllib3.exceptions.ReadTimeoutError: HTTPConnectionPool(host='172.17.0.1', port=8080): Read timed out. (read timeout=5)

During handling of the above exception, another exception occurred:

Traceback (most recent call last):
  File "/code/service.py", line 19, in _request
    "Content-Type": "application/json"}, timeout=5).text
  File "/usr/local/lib/python3.6/dist-packages/requests/api.py", line 119, in post
    return request('post', url, data=data, json=json, **kwargs)
  File "/usr/local/lib/python3.6/dist-packages/requests/api.py", line 61, in request
    return session.request(method=method, url=url, **kwargs)
  File "/usr/local/lib/python3.6/dist-packages/requests/sessions.py", line 530, in request
    resp = self.send(prep, **send_kwargs)
  File "/usr/local/lib/python3.6/dist-packages/requests/sessions.py", line 643, in send
    r = adapter.send(request, **kwargs)
  File "/usr/local/lib/python3.6/dist-packages/requests/adapters.py", line 529, in send
    raise ReadTimeout(e, request=request)
requests.exceptions.ReadTimeout: HTTPConnectionPool(host='172.17.0.1', port=8080): Read timed out. (read timeout=5)

During handling of the above exception, another exception occurred:

Traceback (most recent call last):
  File "/code/service.py", line 42, in <module>
    service.heartbeat()
  File "/code/service.py", line 35, in heartbeat
    self._request(data)
  File "/code/service.py", line 22, in _request
    raise JudgeServiceError("Heartbeat request failed")
exception.JudgeServiceError
2020-11-07 08:03:02,589 ERROR HTTPConnectionPool(host='172.17.0.1', port=8080): Read timed out. (read timeout=5)
Traceback (most recent call last):
  File "/usr/local/lib/python3.6/dist-packages/urllib3/connectionpool.py", line 426, in _make_request
    six.raise_from(e, None)
  File "<string>", line 3, in raise_from
  File "/usr/local/lib/python3.6/dist-packages/urllib3/connectionpool.py", line 421, in _make_request
    httplib_response = conn.getresponse()
  File "/usr/lib/python3.6/http/client.py", line 1356, in getresponse
    response.begin()
  File "/usr/lib/python3.6/http/client.py", line 307, in begin
    version, status, reason = self._read_status()
  File "/usr/lib/python3.6/http/client.py", line 268, in _read_status
    line = str(self.fp.readline(_MAXLINE + 1), "iso-8859-1")
  File "/usr/lib/python3.6/socket.py", line 586, in readinto
    return self._sock.recv_into(b)
socket.timeout: timed out

During handling of the above exception, another exception occurred:

Traceback (most recent call last):
  File "/usr/local/lib/python3.6/dist-packages/requests/adapters.py", line 449, in send
    timeout=timeout
  File "/usr/local/lib/python3.6/dist-packages/urllib3/connectionpool.py", line 725, in urlopen
    method, url, error=e, _pool=self, _stacktrace=sys.exc_info()[2]
  File "/usr/local/lib/python3.6/dist-packages/urllib3/util/retry.py", line 403, in increment
    raise six.reraise(type(error), error, _stacktrace)
  File "/usr/local/lib/python3.6/dist-packages/urllib3/packages/six.py", line 735, in reraise
    raise value
  File "/usr/local/lib/python3.6/dist-packages/urllib3/connectionpool.py", line 677, in urlopen
    chunked=chunked,
  File "/usr/local/lib/python3.6/dist-packages/urllib3/connectionpool.py", line 428, in _make_request
    self._raise_timeout(err=e, url=url, timeout_value=read_timeout)
  File "/usr/local/lib/python3.6/dist-packages/urllib3/connectionpool.py", line 336, in _raise_timeout
    self, url, "Read timed out. (read timeout=%s)" % timeout_value
urllib3.exceptions.ReadTimeoutError: HTTPConnectionPool(host='172.17.0.1', port=8080): Read timed out. (read timeout=5)

During handling of the above exception, another exception occurred:

Traceback (most recent call last):
  File "/code/service.py", line 19, in _request
    "Content-Type": "application/json"}, timeout=5).text
  File "/usr/local/lib/python3.6/dist-packages/requests/api.py", line 119, in post
    return request('post', url, data=data, json=json, **kwargs)
  File "/usr/local/lib/python3.6/dist-packages/requests/api.py", line 61, in request
    return session.request(method=method, url=url, **kwargs)
  File "/usr/local/lib/python3.6/dist-packages/requests/sessions.py", line 530, in request
    resp = self.send(prep, **send_kwargs)
  File "/usr/local/lib/python3.6/dist-packages/requests/sessions.py", line 643, in send
    r = adapter.send(request, **kwargs)
  File "/usr/local/lib/python3.6/dist-packages/requests/adapters.py", line 529, in send
    raise ReadTimeout(e, request=request)
requests.exceptions.ReadTimeout: HTTPConnectionPool(host='172.17.0.1', port=8080): Read timed out. (read timeout=5)
2020-11-07 08:03:02,590 ERROR 
Traceback (most recent call last):
  File "/usr/local/lib/python3.6/dist-packages/urllib3/connectionpool.py", line 426, in _make_request
    six.raise_from(e, None)
  File "<string>", line 3, in raise_from
  File "/usr/local/lib/python3.6/dist-packages/urllib3/connectionpool.py", line 421, in _make_request
    httplib_response = conn.getresponse()
  File "/usr/lib/python3.6/http/client.py", line 1356, in getresponse
    response.begin()
  File "/usr/lib/python3.6/http/client.py", line 307, in begin
    version, status, reason = self._read_status()
  File "/usr/lib/python3.6/http/client.py", line 268, in _read_status
    line = str(self.fp.readline(_MAXLINE + 1), "iso-8859-1")
  File "/usr/lib/python3.6/socket.py", line 586, in readinto
    return self._sock.recv_into(b)
socket.timeout: timed out

During handling of the above exception, another exception occurred:

Traceback (most recent call last):
  File "/usr/local/lib/python3.6/dist-packages/requests/adapters.py", line 449, in send
    timeout=timeout
  File "/usr/local/lib/python3.6/dist-packages/urllib3/connectionpool.py", line 725, in urlopen
    method, url, error=e, _pool=self, _stacktrace=sys.exc_info()[2]
  File "/usr/local/lib/python3.6/dist-packages/urllib3/util/retry.py", line 403, in increment
    raise six.reraise(type(error), error, _stacktrace)
  File "/usr/local/lib/python3.6/dist-packages/urllib3/packages/six.py", line 735, in reraise
    raise value
  File "/usr/local/lib/python3.6/dist-packages/urllib3/connectionpool.py", line 677, in urlopen
    chunked=chunked,
  File "/usr/local/lib/python3.6/dist-packages/urllib3/connectionpool.py", line 428, in _make_request
    self._raise_timeout(err=e, url=url, timeout_value=read_timeout)
  File "/usr/local/lib/python3.6/dist-packages/urllib3/connectionpool.py", line 336, in _raise_timeout
    self, url, "Read timed out. (read timeout=%s)" % timeout_value
urllib3.exceptions.ReadTimeoutError: HTTPConnectionPool(host='172.17.0.1', port=8080): Read timed out. (read timeout=5)

During handling of the above exception, another exception occurred:

Traceback (most recent call last):
  File "/code/service.py", line 19, in _request
    "Content-Type": "application/json"}, timeout=5).text
  File "/usr/local/lib/python3.6/dist-packages/requests/api.py", line 119, in post
    return request('post', url, data=data, json=json, **kwargs)
  File "/usr/local/lib/python3.6/dist-packages/requests/api.py", line 61, in request
    return session.request(method=method, url=url, **kwargs)
  File "/usr/local/lib/python3.6/dist-packages/requests/sessions.py", line 530, in request
    resp = self.send(prep, **send_kwargs)
  File "/usr/local/lib/python3.6/dist-packages/requests/sessions.py", line 643, in send
    r = adapter.send(request, **kwargs)
  File "/usr/local/lib/python3.6/dist-packages/requests/adapters.py", line 529, in send
    raise ReadTimeout(e, request=request)
requests.exceptions.ReadTimeout: HTTPConnectionPool(host='172.17.0.1', port=8080): Read timed out. (read timeout=5)

During handling of the above exception, another exception occurred:

Traceback (most recent call last):
  File "/code/service.py", line 42, in <module>
    service.heartbeat()
  File "/code/service.py", line 35, in heartbeat
    self._request(data)
  File "/code/service.py", line 22, in _request
    raise JudgeServiceError("Heartbeat request failed")
exception.JudgeServiceError
2020-11-07 08:03:28,443 ERROR HTTPConnectionPool(host='172.17.0.1', port=8080): Max retries exceeded with url: /judge_server/heartbeat (Caused by NewConnectionError('<urllib3.connection.HTTPConnection object at 0x7f79b50b2a20>: Failed to establish a new connection: [Errno 111] Connection refused',))
Traceback (most recent call last):
  File "/usr/local/lib/python3.6/dist-packages/urllib3/connection.py", line 160, in _new_conn
    (self._dns_host, self.port), self.timeout, **extra_kw
  File "/usr/local/lib/python3.6/dist-packages/urllib3/util/connection.py", line 84, in create_connection
    raise err
  File "/usr/local/lib/python3.6/dist-packages/urllib3/util/connection.py", line 74, in create_connection
    sock.connect(sa)
ConnectionRefusedError: [Errno 111] Connection refused

During handling of the above exception, another exception occurred:

Traceback (most recent call last):
  File "/usr/local/lib/python3.6/dist-packages/urllib3/connectionpool.py", line 677, in urlopen
    chunked=chunked,
  File "/usr/local/lib/python3.6/dist-packages/urllib3/connectionpool.py", line 392, in _make_request
    conn.request(method, url, **httplib_request_kw)
  File "/usr/lib/python3.6/http/client.py", line 1264, in request
    self._send_request(method, url, body, headers, encode_chunked)
  File "/usr/lib/python3.6/http/client.py", line 1310, in _send_request
    self.endheaders(body, encode_chunked=encode_chunked)
  File "/usr/lib/python3.6/http/client.py", line 1259, in endheaders
    self._send_output(message_body, encode_chunked=encode_chunked)
  File "/usr/lib/python3.6/http/client.py", line 1038, in _send_output
    self.send(msg)
  File "/usr/lib/python3.6/http/client.py", line 976, in send
    self.connect()
  File "/usr/local/lib/python3.6/dist-packages/urllib3/connection.py", line 187, in connect
    conn = self._new_conn()
  File "/usr/local/lib/python3.6/dist-packages/urllib3/connection.py", line 172, in _new_conn
    self, "Failed to establish a new connection: %s" % e
urllib3.exceptions.NewConnectionError: <urllib3.connection.HTTPConnection object at 0x7f79b50b2a20>: Failed to establish a new connection: [Errno 111] Connection refused

During handling of the above exception, another exception occurred:

Traceback (most recent call last):
  File "/usr/local/lib/python3.6/dist-packages/requests/adapters.py", line 449, in send
    timeout=timeout
  File "/usr/local/lib/python3.6/dist-packages/urllib3/connectionpool.py", line 725, in urlopen
    method, url, error=e, _pool=self, _stacktrace=sys.exc_info()[2]
  File "/usr/local/lib/python3.6/dist-packages/urllib3/util/retry.py", line 439, in increment
    raise MaxRetryError(_pool, url, error or ResponseError(cause))
urllib3.exceptions.MaxRetryError: HTTPConnectionPool(host='172.17.0.1', port=8080): Max retries exceeded with url: /judge_server/heartbeat (Caused by NewConnectionError('<urllib3.connection.HTTPConnection object at 0x7f79b50b2a20>: Failed to establish a new connection: [Errno 111] Connection refused',))

During handling of the above exception, another exception occurred:

Traceback (most recent call last):
  File "/code/service.py", line 19, in _request
    "Content-Type": "application/json"}, timeout=5).text
  File "/usr/local/lib/python3.6/dist-packages/requests/api.py", line 119, in post
    return request('post', url, data=data, json=json, **kwargs)
  File "/usr/local/lib/python3.6/dist-packages/requests/api.py", line 61, in request
    return session.request(method=method, url=url, **kwargs)
  File "/usr/local/lib/python3.6/dist-packages/requests/sessions.py", line 530, in request
    resp = self.send(prep, **send_kwargs)
  File "/usr/local/lib/python3.6/dist-packages/requests/sessions.py", line 643, in send
    r = adapter.send(request, **kwargs)
  File "/usr/local/lib/python3.6/dist-packages/requests/adapters.py", line 516, in send
    raise ConnectionError(e, request=request)
requests.exceptions.ConnectionError: HTTPConnectionPool(host='172.17.0.1', port=8080): Max retries exceeded with url: /judge_server/heartbeat (Caused by NewConnectionError('<urllib3.connection.HTTPConnection object at 0x7f79b50b2a20>: Failed to establish a new connection: [Errno 111] Connection refused',))
2020-11-07 08:03:28,444 ERROR 
Traceback (most recent call last):
  File "/usr/local/lib/python3.6/dist-packages/urllib3/connection.py", line 160, in _new_conn
    (self._dns_host, self.port), self.timeout, **extra_kw
  File "/usr/local/lib/python3.6/dist-packages/urllib3/util/connection.py", line 84, in create_connection
    raise err
  File "/usr/local/lib/python3.6/dist-packages/urllib3/util/connection.py", line 74, in create_connection
    sock.connect(sa)
ConnectionRefusedError: [Errno 111] Connection refused

During handling of the above exception, another exception occurred:

Traceback (most recent call last):
  File "/usr/local/lib/python3.6/dist-packages/urllib3/connectionpool.py", line 677, in urlopen
    chunked=chunked,
  File "/usr/local/lib/python3.6/dist-packages/urllib3/connectionpool.py", line 392, in _make_request
    conn.request(method, url, **httplib_request_kw)
  File "/usr/lib/python3.6/http/client.py", line 1264, in request
    self._send_request(method, url, body, headers, encode_chunked)
  File "/usr/lib/python3.6/http/client.py", line 1310, in _send_request
    self.endheaders(body, encode_chunked=encode_chunked)
  File "/usr/lib/python3.6/http/client.py", line 1259, in endheaders
    self._send_output(message_body, encode_chunked=encode_chunked)
  File "/usr/lib/python3.6/http/client.py", line 1038, in _send_output
    self.send(msg)
  File "/usr/lib/python3.6/http/client.py", line 976, in send
    self.connect()
  File "/usr/local/lib/python3.6/dist-packages/urllib3/connection.py", line 187, in connect
    conn = self._new_conn()
  File "/usr/local/lib/python3.6/dist-packages/urllib3/connection.py", line 172, in _new_conn
    self, "Failed to establish a new connection: %s" % e
urllib3.exceptions.NewConnectionError: <urllib3.connection.HTTPConnection object at 0x7f79b50b2a20>: Failed to establish a new connection: [Errno 111] Connection refused

During handling of the above exception, another exception occurred:

Traceback (most recent call last):
  File "/usr/local/lib/python3.6/dist-packages/requests/adapters.py", line 449, in send
    timeout=timeout
  File "/usr/local/lib/python3.6/dist-packages/urllib3/connectionpool.py", line 725, in urlopen
    method, url, error=e, _pool=self, _stacktrace=sys.exc_info()[2]
  File "/usr/local/lib/python3.6/dist-packages/urllib3/util/retry.py", line 439, in increment
    raise MaxRetryError(_pool, url, error or ResponseError(cause))
urllib3.exceptions.MaxRetryError: HTTPConnectionPool(host='172.17.0.1', port=8080): Max retries exceeded with url: /judge_server/heartbeat (Caused by NewConnectionError('<urllib3.connection.HTTPConnection object at 0x7f79b50b2a20>: Failed to establish a new connection: [Errno 111] Connection refused',))

During handling of the above exception, another exception occurred:

Traceback (most recent call last):
  File "/code/service.py", line 19, in _request
    "Content-Type": "application/json"}, timeout=5).text
  File "/usr/local/lib/python3.6/dist-packages/requests/api.py", line 119, in post
    return request('post', url, data=data, json=json, **kwargs)
  File "/usr/local/lib/python3.6/dist-packages/requests/api.py", line 61, in request
    return session.request(method=method, url=url, **kwargs)
  File "/usr/local/lib/python3.6/dist-packages/requests/sessions.py", line 530, in request
    resp = self.send(prep, **send_kwargs)
  File "/usr/local/lib/python3.6/dist-packages/requests/sessions.py", line 643, in send
    r = adapter.send(request, **kwargs)
  File "/usr/local/lib/python3.6/dist-packages/requests/adapters.py", line 516, in send
    raise ConnectionError(e, request=request)
requests.exceptions.ConnectionError: HTTPConnectionPool(host='172.17.0.1', port=8080): Max retries exceeded with url: /judge_server/heartbeat (Caused by NewConnectionError('<urllib3.connection.HTTPConnection object at 0x7f79b50b2a20>: Failed to establish a new connection: [Errno 111] Connection refused',))

During handling of the above exception, another exception occurred:

Traceback (most recent call last):
  File "/code/service.py", line 42, in <module>
    service.heartbeat()
  File "/code/service.py", line 35, in heartbeat
    self._request(data)
  File "/code/service.py", line 22, in _request
    raise JudgeServiceError("Heartbeat request failed")
exception.JudgeServiceError
2020-11-07 08:03:33,611 ERROR HTTPConnectionPool(host='172.17.0.1', port=8080): Max retries exceeded with url: /judge_server/heartbeat (Caused by NewConnectionError('<urllib3.connection.HTTPConnection object at 0x7f94df76fa90>: Failed to establish a new connection: [Errno 111] Connection refused',))
Traceback (most recent call last):
  File "/usr/local/lib/python3.6/dist-packages/urllib3/connection.py", line 160, in _new_conn
    (self._dns_host, self.port), self.timeout, **extra_kw
  File "/usr/local/lib/python3.6/dist-packages/urllib3/util/connection.py", line 84, in create_connection
    raise err
  File "/usr/local/lib/python3.6/dist-packages/urllib3/util/connection.py", line 74, in create_connection
    sock.connect(sa)
ConnectionRefusedError: [Errno 111] Connection refused

During handling of the above exception, another exception occurred:

Traceback (most recent call last):
  File "/usr/local/lib/python3.6/dist-packages/urllib3/connectionpool.py", line 677, in urlopen
    chunked=chunked,
  File "/usr/local/lib/python3.6/dist-packages/urllib3/connectionpool.py", line 392, in _make_request
    conn.request(method, url, **httplib_request_kw)
  File "/usr/lib/python3.6/http/client.py", line 1264, in request
    self._send_request(method, url, body, headers, encode_chunked)
  File "/usr/lib/python3.6/http/client.py", line 1310, in _send_request
    self.endheaders(body, encode_chunked=encode_chunked)
  File "/usr/lib/python3.6/http/client.py", line 1259, in endheaders
    self._send_output(message_body, encode_chunked=encode_chunked)
  File "/usr/lib/python3.6/http/client.py", line 1038, in _send_output
    self.send(msg)
  File "/usr/lib/python3.6/http/client.py", line 976, in send
    self.connect()
  File "/usr/local/lib/python3.6/dist-packages/urllib3/connection.py", line 187, in connect
    conn = self._new_conn()
  File "/usr/local/lib/python3.6/dist-packages/urllib3/connection.py", line 172, in _new_conn
    self, "Failed to establish a new connection: %s" % e
urllib3.exceptions.NewConnectionError: <urllib3.connection.HTTPConnection object at 0x7f94df76fa90>: Failed to establish a new connection: [Errno 111] Connection refused

During handling of the above exception, another exception occurred:

Traceback (most recent call last):
  File "/usr/local/lib/python3.6/dist-packages/requests/adapters.py", line 449, in send
    timeout=timeout
  File "/usr/local/lib/python3.6/dist-packages/urllib3/connectionpool.py", line 725, in urlopen
    method, url, error=e, _pool=self, _stacktrace=sys.exc_info()[2]
  File "/usr/local/lib/python3.6/dist-packages/urllib3/util/retry.py", line 439, in increment
    raise MaxRetryError(_pool, url, error or ResponseError(cause))
urllib3.exceptions.MaxRetryError: HTTPConnectionPool(host='172.17.0.1', port=8080): Max retries exceeded with url: /judge_server/heartbeat (Caused by NewConnectionError('<urllib3.connection.HTTPConnection object at 0x7f94df76fa90>: Failed to establish a new connection: [Errno 111] Connection refused',))

During handling of the above exception, another exception occurred:

Traceback (most recent call last):
  File "/code/service.py", line 19, in _request
    "Content-Type": "application/json"}, timeout=5).text
  File "/usr/local/lib/python3.6/dist-packages/requests/api.py", line 119, in post
    return request('post', url, data=data, json=json, **kwargs)
  File "/usr/local/lib/python3.6/dist-packages/requests/api.py", line 61, in request
    return session.request(method=method, url=url, **kwargs)
  File "/usr/local/lib/python3.6/dist-packages/requests/sessions.py", line 530, in request
    resp = self.send(prep, **send_kwargs)
  File "/usr/local/lib/python3.6/dist-packages/requests/sessions.py", line 643, in send
    r = adapter.send(request, **kwargs)
  File "/usr/local/lib/python3.6/dist-packages/requests/adapters.py", line 516, in send
    raise ConnectionError(e, request=request)
requests.exceptions.ConnectionError: HTTPConnectionPool(host='172.17.0.1', port=8080): Max retries exceeded with url: /judge_server/heartbeat (Caused by NewConnectionError('<urllib3.connection.HTTPConnection object at 0x7f94df76fa90>: Failed to establish a new connection: [Errno 111] Connection refused',))
2020-11-07 08:03:33,612 ERROR 
Traceback (most recent call last):
  File "/usr/local/lib/python3.6/dist-packages/urllib3/connection.py", line 160, in _new_conn
    (self._dns_host, self.port), self.timeout, **extra_kw
  File "/usr/local/lib/python3.6/dist-packages/urllib3/util/connection.py", line 84, in create_connection
    raise err
  File "/usr/local/lib/python3.6/dist-packages/urllib3/util/connection.py", line 74, in create_connection
    sock.connect(sa)
ConnectionRefusedError: [Errno 111] Connection refused

During handling of the above exception, another exception occurred:

Traceback (most recent call last):
  File "/usr/local/lib/python3.6/dist-packages/urllib3/connectionpool.py", line 677, in urlopen
    chunked=chunked,
  File "/usr/local/lib/python3.6/dist-packages/urllib3/connectionpool.py", line 392, in _make_request
    conn.request(method, url, **httplib_request_kw)
  File "/usr/lib/python3.6/http/client.py", line 1264, in request
    self._send_request(method, url, body, headers, encode_chunked)
  File "/usr/lib/python3.6/http/client.py", line 1310, in _send_request
    self.endheaders(body, encode_chunked=encode_chunked)
  File "/usr/lib/python3.6/http/client.py", line 1259, in endheaders
    self._send_output(message_body, encode_chunked=encode_chunked)
  File "/usr/lib/python3.6/http/client.py", line 1038, in _send_output
    self.send(msg)
  File "/usr/lib/python3.6/http/client.py", line 976, in send
    self.connect()
  File "/usr/local/lib/python3.6/dist-packages/urllib3/connection.py", line 187, in connect
    conn = self._new_conn()
  File "/usr/local/lib/python3.6/dist-packages/urllib3/connection.py", line 172, in _new_conn
    self, "Failed to establish a new connection: %s" % e
urllib3.exceptions.NewConnectionError: <urllib3.connection.HTTPConnection object at 0x7f94df76fa90>: Failed to establish a new connection: [Errno 111] Connection refused

During handling of the above exception, another exception occurred:

Traceback (most recent call last):
  File "/usr/local/lib/python3.6/dist-packages/requests/adapters.py", line 449, in send
    timeout=timeout
  File "/usr/local/lib/python3.6/dist-packages/urllib3/connectionpool.py", line 725, in urlopen
    method, url, error=e, _pool=self, _stacktrace=sys.exc_info()[2]
  File "/usr/local/lib/python3.6/dist-packages/urllib3/util/retry.py", line 439, in increment
    raise MaxRetryError(_pool, url, error or ResponseError(cause))
urllib3.exceptions.MaxRetryError: HTTPConnectionPool(host='172.17.0.1', port=8080): Max retries exceeded with url: /judge_server/heartbeat (Caused by NewConnectionError('<urllib3.connection.HTTPConnection object at 0x7f94df76fa90>: Failed to establish a new connection: [Errno 111] Connection refused',))

During handling of the above exception, another exception occurred:

Traceback (most recent call last):
  File "/code/service.py", line 19, in _request
    "Content-Type": "application/json"}, timeout=5).text
  File "/usr/local/lib/python3.6/dist-packages/requests/api.py", line 119, in post
    return request('post', url, data=data, json=json, **kwargs)
  File "/usr/local/lib/python3.6/dist-packages/requests/api.py", line 61, in request
    return session.request(method=method, url=url, **kwargs)
  File "/usr/local/lib/python3.6/dist-packages/requests/sessions.py", line 530, in request
    resp = self.send(prep, **send_kwargs)
  File "/usr/local/lib/python3.6/dist-packages/requests/sessions.py", line 643, in send
    r = adapter.send(request, **kwargs)
  File "/usr/local/lib/python3.6/dist-packages/requests/adapters.py", line 516, in send
    raise ConnectionError(e, request=request)
requests.exceptions.ConnectionError: HTTPConnectionPool(host='172.17.0.1', port=8080): Max retries exceeded with url: /judge_server/heartbeat (Caused by NewConnectionError('<urllib3.connection.HTTPConnection object at 0x7f94df76fa90>: Failed to establish a new connection: [Errno 111] Connection refused',))

During handling of the above exception, another exception occurred:

Traceback (most recent call last):
  File "/code/service.py", line 42, in <module>
    service.heartbeat()
  File "/code/service.py", line 35, in heartbeat
    self._request(data)
  File "/code/service.py", line 22, in _request
    raise JudgeServiceError("Heartbeat request failed")
exception.JudgeServiceError
